Workbook

Sheet RELACION ESTUDIANTES - 2022
B2: PROF. FARFAN - MECANICA DE PRODUCCION | C2: PROF. FARFAN - MECANICA DE PROD. | D2: PROF. - COMPUTACION
B5: 3ro "D" | C5: 5to "I" | D5: 5to "R"
A6: 1 | B6: CASAVILCA ACOSTA YZUHAIM HUGO ALBERTO | C6: CALDERON FALCON DORIAM JOSUE | D6: APUMAITA GUTIERREZ JULIO LUCIANO | F6: APUMAITA GUTIERREZ, JULIO LUCIANO | J6: =FIND(",",F6) -> 19 | K6: =MID(F6,J6+2,10) -> JULIO LUCI | L6: =FIND(" ",K6) -> 6 | M6: =MID(K6,1,L6) -> JULIO | N6: =FIND(" ",F6) -> 9 | O6: =MID(F6,1,N6) -> APUMAITA | Q6: =LOWER(M6) -> julio | R6: =LOWER(O6) -> apumaita | S6: =LEFT(Q6,2) -> ju | T6: =CONCATENATE(S6,R6) -> juapumaita | U6: @xyz.com | V6: =CONCATENATE(T6,U6) -> juapumaita @xyz.com | W6: =FIND(" ",T6) -> 11 | X6: =MID(T6,1,W6-1) -> juapumaita | Z6: =CONCATENATE(X6,U6) -> juapumaita@xyz.com
A7: 2 | B7: CASTRO VARGAS JHORDAN ANDREE WILLIAN | C7: CAMPOS PALOMINO MAXIMO NASSIR | D7: CABRERA ORTIZ THIAGO ARMANDO | F7: CABRERA ORTIZ, THIAGO ARMANDO | J7: =FIND(",",F7) -> 14 | K7: =MID(F7,J7+2,10) -> THIAGO ARM | L7: =FIND(" ",K7) -> 7 | M7: =MID(K7,1,L7) -> THIAGO | N7: =FIND(" ",F7) -> 8 | O7: =MID(F7,1,N7) -> CABRERA | Q7: =LOWER(M7) -> thiago | R7: =LOWER(O7) -> cabrera | S7: =LEFT(Q7,2) -> th | T7: =CONCATENATE(S7,R7) -> thcabrera | U7: @xyz.com | V7: =CONCATENATE(T7,U7) -> thcabrera @xyz.com | W7: =FIND(" ",T7) -> 10 | X7: =MID(T7,1,W7-1) -> thcabrera | Z7: =CONCATENATE(X7,U7) -> thcabrera@xyz.com
A8: 3 | B8: CONDE GAMBOA JHONATAN RODRIGO | C8: CHUQUIZUTA VALENCIA FRANKLIN YAZID | D8: CACERES CAHUANA JESUS ANDRES | F8: CACERES CAHUANA, JESUS ANDRES | J8: =FIND(",",F8) -> 16 | K8: =MID(F8,J8+2,10) -> JESUS ANDR | L8: =FIND(" ",K8) -> 6 | M8: =MID(K8,1,L8) -> JESUS | N8: =FIND(" ",F8) -> 8 | O8: =MID(F8,1,N8) -> CACERES | Q8: =LOWER(M8) -> jesus | R8: =LOWER(O8) -> caceres | S8: =LEFT(Q8,2) -> je | T8: =CONCATENATE(S8,R8) -> jecaceres | U8: @xyz.com | V8: =CONCATENATE(T8,U8) -> jecaceres @xyz.com | W8: =FIND(" ",T8) -> 10 | X8: =MID(T8,1,W8-1) -> jecaceres | Z8: =CONCATENATE(X8,U8) -> jecaceres@xyz.com
A9: 4 | B9: CUADROS ZEVALLOS ANGELO DAVID | C9: COTAQUISPE GALVEZ YOJAN ANDRES | D9: DE LA CRUZ SIGUAS LUIS ALBERTO | F9: DE LA CRUZ SIGUAS, LUIS ALBERTO | J9: =FIND(",",F9) -> 18 | K9: =MID(F9,J9+2,10) -> LUIS ALBER | L9: =FIND(" ",K9) -> 5 | M9: =MID(K9,1,L9) -> LUIS | N9: =FIND(" ",F9) -> 3 | O9: =MID(F9,1,N9) -> DE | Q9: =LOWER(M9) -> luis | R9: =LOWER(O9) -> de | S9: =LEFT(Q9,2) -> lu | T9: =CONCATENATE(S9,R9) -> lude | U9: @xyz.com | V9: =CONCATENATE(T9,U9) -> lude @xyz.com | W9: =FIND(" ",T9) -> 5 | X9: =MID(T9,1,W9-1) -> lude | Z9: =CONCATENATE(X9,U9) -> lude@xyz.com
A10: 5 | B10: GALINDO HERNANDEZ EMERSON FELIPE | C10: HUAMANI PAUCAR LUIS ALFREDO | D10: HERNANDEZ PEÑA JOSEPH ANDREE | F10: HERNANDEZ PEÑA, JOSEPH ANDREE | J10: =FIND(",",F10) -> 15 | K10: =MID(F10,J10+2,10) -> JOSEPH AN | L10: =FIND(" ",K10) -> 1 | M10: =MID(K10,1,L10) | N10: =FIND(" ",F10) -> 10 | O10: =MID(F10,1,N10) -> HERNANDEZ | Q10: =LOWER(M10) | R10: =LOWER(O10) -> hernandez | S10: =LEFT(Q10,2) | T10: =CONCATENATE(S10,R10) -> hernandez | U10: @xyz.com | V10: =CONCATENATE(T10,U10) -> hernandez @xyz.com | W10: =FIND(" ",T10) -> 1 | X10: =MID(T10,1,W10-1) | Z10: =CONCATENATE(X10,U10) -> @xyz.com
A11: 6 | B11: HERNANDEZ ENRIQUEZ JARED MIGUEL | C11: HUARCAYA BACAS HENRY VICENTE | D11: JUAREZ LEGUA VICTOR DANIEL | F11: JUAREZ LEGUA, VICTOR DANIEL | J11: =FIND(",",F11) -> 13 | K11: =MID(F11,J11+2,10) -> VICTOR DAN | L11: =FIND(" ",K11) -> 7 | M11: =MID(K11,1,L11) -> VICTOR | N11: =FIND(" ",F11) -> 7 | O11: =MID(F11,1,N11) -> JUAREZ | Q11: =LOWER(M11) -> victor | R11: =LOWER(O11) -> juarez | S11: =LEFT(Q11,2) -> vi | T11: =CONCATENATE(S11,R11) -> vijuarez | U11: @xyz.com | V11: =CONCATENATE(T11,U11) -> vijuarez @xyz.com | W11: =FIND(" ",T11) -> 9 | X11: =MID(T11,1,W11-1) -> vijuarez | Z11: =CONCATENATE(X11,U11) -> vijuarez@xyz.com
A12: 7 | B12: HERNANDEZ MUNIVE NICOLAS ERNESTO | C12: HUAYHUAMEZA LEÑAN DEYVIS | D12: MEJIA SIMON VICENTE MISAEL | F12: MEJIA SIMON, VICENTE MISAEL | J12: =FIND(",",F12) -> 12 | K12: =MID(F12,J12+2,10) -> VICENTE MI | L12: =FIND(" ",K12) -> 8 | M12: =MID(K12,1,L12) -> VICENTE | N12: =FIND(" ",F12) -> 6 | O12: =MID(F12,1,N12) -> MEJIA | Q12: =LOWER(M12) -> vicente | R12: =LOWER(O12) -> mejia | S12: =LEFT(Q12,2) -> vi | T12: =CONCATENATE(S12,R12) -> vimejia | U12: @xyz.com | V12: =CONCATENATE(T12,U12) -> vimejia @xyz.com | W12: =FIND(" ",T12) -> 8 | X12: =MID(T12,1,W12-1) -> vimejia | Z12: =CONCATENATE(X12,U12) -> vimejia@xyz.com
A13: 8 | B13: NAVAS GOMEZ BENJAMIN HUMBERTO | C13: JUSCAMAYTA HUARACC YOSSIMAR BAYRON | D13: MEZA CARDENAS FERNANDO ALEXANDER | F13: MEZA CARDENAS, FERNANDO ALEXANDER | J13: =FIND(",",F13) -> 14 | K13: =MID(F13,J13+2,10) -> FERNANDO A | L13: =FIND(" ",K13) -> 9 | M13: =MID(K13,1,L13) -> FERNANDO | N13: =FIND(" ",F13) -> 5 | O13: =MID(F13,1,N13) -> MEZA | Q13: =LOWER(M13) -> fernando | R13: =LOWER(O13) -> meza | S13: =LEFT(Q13,2) -> fe | T13: =CONCATENATE(S13,R13) -> femeza | U13: @xyz.com | V13: =CONCATENATE(T13,U13) -> femeza @xyz.com | W13: =FIND(" ",T13) -> 7 | X13: =MID(T13,1,W13-1) -> femeza | Z13: =CONCATENATE(X13,U13) -> femeza@xyz.com
A14: 9 | B14: PACHECO ESPILLCO MATIAS DEYAIR | C14: LEVANO GALINDO CRISTOPHER ANDRES | D14: MISAICO CHAHUAILA JUAN DAVID | F14: MISAICO CHAHUAILA, JUAN DAVID | J14: =FIND(",",F14) -> 18 | K14: =MID(F14,J14+2,10) -> JUAN DAVID | L14: =FIND(" ",K14) -> 5 | M14: =MID(K14,1,L14) -> JUAN | N14: =FIND(" ",F14) -> 8 | O14: =MID(F14,1,N14) -> MISAICO | Q14: =LOWER(M14) -> juan | R14: =LOWER(O14) -> misaico | S14: =LEFT(Q14,2) -> ju | T14: =CONCATENATE(S14,R14) -> jumisaico | U14: @xyz.com | V14: =CONCATENATE(T14,U14) -> jumisaico @xyz.com | W14: =FIND(" ",T14) -> 10 | X14: =MID(T14,1,W14-1) -> jumisaico | Z14: =CONCATENATE(X14,U14) -> jumisaico@xyz.com
A15: 10 | B15: RAMIREZ ESCRIBA JHERCY HUSCIEL | C15: LINARES ZAPATA CARLOS ALBERTO | D15: MUÑOZ QUINTANILLA JACKXEL EDUARDO | F15: MUÑOZ QUINTANILLA, JACKXEL EDUARDO | J15: =FIND(",",F15) -> 18 | K15: =MID(F15,J15+2,10) -> JACKXEL ED | L15: =FIND(" ",K15) -> 8 | M15: =MID(K15,1,L15) -> JACKXEL | N15: =FIND(" ",F15) -> 6 | O15: =MID(F15,1,N15) -> MUÑOZ | Q15: =LOWER(M15) -> jackxel | R15: =LOWER(O15) -> muñoz | S15: =LEFT(Q15,2) -> ja | T15: =CONCATENATE(S15,R15) -> jamuñoz | U15: @xyz.com | V15: =CONCATENATE(T15,U15) -> jamuñoz @xyz.com | W15: =FIND(" ",T15) -> 8 | X15: =MID(T15,1,W15-1) -> jamuñoz | Z15: =CONCATENATE(X15,U15) -> jamuñoz@xyz.com
A16: 11 | B16: SANCHEZ SANTIAGO KALEB MOISES | C16: MOZO HUAYRA PEDRO CALEB | D16: PEÑA ASCENCIO CESAR LUIS | F16: PEÑA ASCENCIO, CESAR LUIS | J16: =FIND(",",F16) -> 14 | K16: =MID(F16,J16+2,10) -> CESAR LUIS | L16: =FIND(" ",K16) -> 6 | M16: =MID(K16,1,L16) -> CESAR | N16: =FIND(" ",F16) -> 5 | O16: =MID(F16,1,N16) -> PEÑA | Q16: =LOWER(M16) -> cesar | R16: =LOWER(O16) -> peña | S16: =LEFT(Q16,2) -> ce | T16: =CONCATENATE(S16,R16) -> cepeña | U16: @xyz.com | V16: =CONCATENATE(T16,U16) -> cepeña @xyz.com | W16: =FIND(" ",T16) -> 7 | X16: =MID(T16,1,W16-1) -> cepeña | Z16: =CONCATENATE(X16,U16) -> cepeña@xyz.com
A17: 12 | B17: SEGOVIA LICAS DANGELO KENDALL | C17: NECOCHEA CASTILLO ANTHONY ORLANDO | D17: SOSA FUENTES UBALDO FRANCISCO | F17: SOSA FUENTES, UBALDO FRANCISCO | J17: =FIND(",",F17) -> 13 | K17: =MID(F17,J17+2,10) -> UBALDO FRA | L17: =FIND(" ",K17) -> 7 | M17: =MID(K17,1,L17) -> UBALDO | N17: =FIND(" ",F17) -> 5 | O17: =MID(F17,1,N17) -> SOSA | Q17: =LOWER(M17) -> ubaldo | R17: =LOWER(O17) -> sosa | S17: =LEFT(Q17,2) -> ub | T17: =CONCATENATE(S17,R17) -> ubsosa | U17: @xyz.com | V17: =CONCATENATE(T17,U17) -> ubsosa @xyz.com | W17: =FIND(" ",T17) -> 7 | X17: =MID(T17,1,W17-1) -> ubsosa | Z17: =CONCATENATE(X17,U17) -> ubsosa@xyz.com
A18: 13 | B18: VELARDE GONZALEZ MARCOS MIGUEL | C18: ÑAÑEZ CARRASQUEL DIEGO ALEJANDRO | J18: =FIND(",",F18) -> #VALUE! | K18: =MID(F18,J18+2,10) -> #VALUE! | L18: =FIND(" ",K18) -> #VALUE! | M18: =MID(K18,1,L18) -> #VALUE! | N18: =FIND(" ",F18) -> #VALUE! | O18: =MID(F18,1,N18) -> #VALUE! | Q18: =LOWER(M18) -> #VALUE! | R18: =LOWER(O18) -> #VALUE! | S18: =LEFT(Q18,2) -> #VALUE! | T18: =CONCATENATE(S18,R18) -> #VALUE! | U18: @xyz.com | V18: =CONCATENATE(T18,U18) -> #VALUE! | W18: =FIND(" ",T18) -> #VALUE! | X18: =MID(T18,1,W18-1) -> #VALUE! | Z18: =CONCATENATE(X18,U18) -> #VALUE!
A19: 14 | B19: YARCURI CRISOSTOMO JUAN DIEGO | C19: PEREZ MUÑOZ SAMIER ALEJANDRO | J19: =FIND(",",F19) -> #VALUE! | K19: =MID(F19,J19+2,10) -> #VALUE! | L19: =FIND(" ",K19) -> #VALUE! | M19: =MID(K19,1,L19) -> #VALUE! | N19: =FIND(" ",F19) -> #VALUE! | O19: =MID(F19,1,N19) -> #VALUE! | Q19: =LOWER(M19) -> #VALUE! | R19: =LOWER(O19) -> #VALUE! | S19: =LEFT(Q19,2) -> #VALUE! | T19: =CONCATENATE(S19,R19) -> #VALUE! | U19: @xyz.com | V19: =CONCATENATE(T19,U19) -> #VALUE! | W19: =FIND(" ",T19) -> #VALUE! | X19: =MID(T19,1,W19-1) -> #VALUE! | Z19: =CONCATENATE(X19,U19) -> #VALUE!
A20: 15 | C20: PICHARDE AQUINO CARLOS GABRIEL | J20: =FIND(",",F20) -> #VALUE! | K20: =MID(F20,J20+2,10) -> #VALUE! | L20: =FIND(" ",K20) -> #VALUE! | M20: =MID(K20,1,L20) -> #VALUE! | N20: =FIND(" ",F20) -> #VALUE! | O20: =MID(F20,1,N20) -> #VALUE! | Q20: =LOWER(M20) -> #VALUE! | R20: =LOWER(O20) -> #VALUE! | S20: =LEFT(Q20,2) -> #VALUE! | T20: =CONCATENATE(S20,R20) -> #VALUE! | U20: @xyz.com | V20: =CONCATENATE(T20,U20) -> #VALUE! | W20: =FIND(" ",T20) -> #VALUE! | X20: =MID(T20,1,W20-1) -> #VALUE! | Z20: =CONCATENATE(X20,U20) -> #VALUE!
A21: 16 | C21: VEGA CANALES ALVEYRO CRISTOBAL | J21: =FIND(",",F21) -> #VALUE! | K21: =MID(F21,J21+2,10) -> #VALUE! | L21: =FIND(" ",K21) -> #VALUE! | M21: =MID(K21,1,L21) -> #VALUE! | N21: =FIND(" ",F21) -> #VALUE! | O21: =MID(F21,1,N21) -> #VALUE! | Q21: =LOWER(M21) -> #VALUE! | R21: =LOWER(O21) -> #VALUE! | S21: =LEFT(Q21,2) -> #VALUE! | T21: =CONCATENATE(S21,R21) -> #VALUE! | U21: @xyz.com | V21: =CONCATENATE(T21,U21) -> #VALUE! | W21: =FIND(" ",T21) -> #VALUE! | X21: =MID(T21,1,W21-1) -> #VALUE! | Z21: =CONCATENATE(X21,U21) -> #VALUE!
A22: 17 | J22: =FIND(",",F22) -> #VALUE! | K22: =MID(F22,J22+2,10) -> #VALUE! | L22: =FIND(" ",K22) -> #VALUE! | M22: =MID(K22,1,L22) -> #VALUE! | N22: =FIND(" ",F22) -> #VALUE! | O22: =MID(F22,1,N22) -> #VALUE! | Q22: =LOWER(M22) -> #VALUE! | R22: =LOWER(O22) -> #VALUE! | S22: =LEFT(Q22,2) -> #VALUE! | T22: =CONCATENATE(S22,R22) -> #VALUE! | U22: @xyz.com | V22: =CONCATENATE(T22,U22) -> #VALUE! | W22: =FIND(" ",T22) -> #VALUE! | X22: =MID(T22,1,W22-1) -> #VALUE! | Z22: =CONCATENATE(X22,U22) -> #VALUE!
A23: 18 | J23: =FIND(",",F23) -> #VALUE! | K23: =MID(F23,J23+2,10) -> #VALUE! | L23: =FIND(" ",K23) -> #VALUE! | M23: =MID(K23,1,L23) -> #VALUE! | N23: =FIND(" ",F23) -> #VALUE! | O23: =MID(F23,1,N23) -> #VALUE! | Q23: =LOWER(M23) -> #VALUE! | R23: =LOWER(O23) -> #VALUE! | S23: =LEFT(Q23,2) -> #VALUE! | T23: =CONCATENATE(S23,R23) -> #VALUE! | U23: @xyz.com | V23: =CONCATENATE(T23,U23) -> #VALUE! | W23: =FIND(" ",T23) -> #VALUE! | X23: =MID(T23,1,W23-1) -> #VALUE! | Z23: =CONCATENATE(X23,U23) -> #VALUE!
A24: 19
A25: 20
A26: 21
A27: 22
A28: 23
A29: 24
A30: 25
A31: 26
A32: 27
A33: 28
A34: 29
A35: 30
... A42: 37

Sheet 3RO-D
B2: REGISTRO AUXILIAR 2025 - 3ER GRADO
B4: 3° "D" | C4: MES DE MAYO AREA DE EPT - ACCIONES REALIZADAS Y SEGUIMIENTO DE ESTUDIANTES | S4: MES DE JUNIO AREA DE EPT - ACCIONES REALIZADAS Y SEGUIMIENTO DE ESTUDIANTES | BE4: MES DE JULIO AREA DE EPT - ACCIONES REALIZADAS Y SEGUIMIENTO DE ESTUDIANTES
A5: N° | B5: APELLIDOS Y NOMBRES | C5: SEM 11 | I5: G | J5: SEM 12 | R5: S | S5: SEM 13 | Z5: E | AA5: ASIST. | AF5: SEM 14 | AM5: F | AN5: SEM 15 | AU5: J | AV5: SEM 16 | BD5: K | BE5: SEM 17 | BL5: L | BM5: ASIST. | BR5: SEM 18 | BZ5: O | CA5: SEM 19 | CJ5: T | CO5: SEM 20
D6: =K6-7 -> 45803 | E6: =D6+1 -> 45804 | F6: =D6+2 -> 45805 | H6: ASIST | I6: PROM | K6: 45810 | L6: =K6+1 -> 45811 | M6: =K6+2 -> 45812 | Q6: ASIST | R6: PROM | T6: =K6+7 -> 45817 | U6: =T6+1 -> 45818 | V6: =T6+2 -> 45819 | W6: FOLDER | X6: CUADENO | Y6: ASIST | Z6: PROM | AG6: =T6+7 -> 45824 | AH6: =AG6+1 -> 45825 | AI6: =AG6+2 -> 45826 | AJ6: EXAMEN | AK6: CARP TRAB | AL6: ASIST | AM6: PROM | AO6: =AG6+7 -> 45831 | AP6: =AO6+1 -> 45832 | AQ6: =AO6+2 -> 45833 | AR6: CyE | AS6: EXAMEN | AT6: ASIST | AU6: PROM | AW6: =AO6+7 -> 45838 | AX6: =AW6+1 -> 45839 | AY6: =AX6+1 -> 45840 | AZ6: EXAMEN | BA6: PLANO | BB6: TIEMPO DE LIN | BC6: ASIST | BD6: PROM | BF6: =AW6+7 -> 45845 | BG6: =BF6+1 -> 45846 | BH6: =BG6+1 -> 45847 | BI6: CARP TRAB | BJ6: EXAMEN | BK6: ASIST | BL6: PROM | BS6: =BF6+7 -> 45852 | BT6: =BS6+1 -> 45853 | BU6: =BS6+2 -> 45854 | BV6: LIM-PC | BW6: FOLDER | BX6: EXAMEN | BY6: ASIST | BZ6: PROM | CB6: =BS6+7 -> 45859 | CC6: =CB6+1 -> 45860 | CD6: =CB6+3 -> 45862 | CE6: FOLDER | CF6: CARP TRAB | CG6: EXAMEN | CH6: DANZA | CI6: ASIST | CJ6: PROM | CU6: ASIST | CV6: PROM | CW6: ASISTENCIA | CX6: EXAMEN | CY6: EXAMEN
A7: 1 | B7: ='RELACION ESTUDIANTES - 2022'!B6 -> CASAVILCA ACOSTA YZUHAIM HUGO ALBERTO | D7: AD | E7: AD | F7: AD | H7: =Q7 -> AD | I7: AD | K7: AD | L7: AD | M7: AD | Q7: =Y7 -> AD | R7: AD | T7: AD | U7: AD | V7: AD | W7: A | Y7: =AL7 -> AD | Z7: AD | AG7: AD | AH7: AD | AI7: B | AK7: AD | AL7: =AT7 -> AD | AM7: A | AO7: DIA | AP7: AD | AQ7: AD | AS7: AD | AT7: =BC7 -> AD | AU7: AD | AW7: A | AX7: AD | AY7: A | AZ7: AD | BC7: =BK7 -> AD | BD7: AD | BF7: AD | BG7: AD | BH7: A | BI7: AD | BJ7: AD | BK7: =BY7 -> AD | BL7: AD | BS7: AD | BT7: AD | BU7: AD | BW7: A | BX7: AD | BY7: =CI7 -> AD | BZ7: AD | CB7: AD | CC7: A | CE7: A | CF7: AD | CG7: AD | CI7: =CW7 -> AD | CJ7: AD | CW7: AD | CX7: A | CY7: AD | CZ7: AD | DA7: =CZ7*2+4 -> #VALUE!
A8: 2 | B8: ='RELACION ESTUDIANTES - 2022'!B7 -> CASTRO VARGAS JHORDAN ANDREE WILLIAN | D8: AD | E8: A | F8: A | H8: =Q8 -> AD | I8: A | K8: A | L8: B | M8: A | Q8: =Y8 -> AD | R8: A | T8: AD | U8: AD | V8: AD | W8: AD | Y8: =AL8 -> AD | Z8: AD | AG8: AD | AH8: AD | AI8: B | AK8: AD | AL8: =AT8 -> AD | AM8: A | AO8: NO | AP8: AD | AQ8: C | AS8: AD | AT8: =BC8 -> AD | AU8: B | AW8: AD | AX8: AD | AY8: B | AZ8: AD | BC8: =BK8 -> AD | BD8: A | BF8: AD | BG8: AD | BH8: A | BI8: AD | BJ8: AD | BK8: =BY8 -> AD | BL8: AD | BS8: AD | BT8: AD | BU8: A | BW8: AD | BX8: AD | BY8: =CI8 -> AD | BZ8: AD | CB8: AD | CC8: B | CE8: AD | CF8: AD | CG8: AD | CI8: =CW8 -> AD | CJ8: A | CW8: AD | CX8: A | CY8: AD | CZ8: AD | DA8: =CZ8*2+4 -> #VALUE!
A9: 3 | B9: ='RELACION ESTUDIANTES - 2022'!B8 -> CONDE GAMBOA JHONATAN RODRIGO | D9: B | E9: A | F9: A | H9: =Q9 -> AD | I9: A | K9: AD | L9: AD | M9: AD | Q9: =Y9 -> AD | R9: AD | T9: AD | U9: AD | V9: AD | W9: A | Y9: =AL9 -> AD | Z9: AD | AG9: AD | AH9: AD | AI9: B | AK9: AD | AL9: =AT9 -> AD | AM9: A | AO9: LAB | AP9: B | AQ9: A | AS9: B | AT9: =BC9 -> AD | AU9: B | AW9: B | AX9: C | AY9: A | AZ9: B | BC9: =BK9 -> AD | BD9: B | BF9: AD | BG9: AD | BH9: A | BI9: AD | BJ9: B | BK9: =BY9 -> AD | BL9: A | BS9: A | BT9: AD | BU9: AD | BW9: A | BX9: B | BY9: =CI9 -> AD | BZ9: A | CB9: AD | CC9: A | CE9: A | CF9: AD | CG9: B | CI9: =CW9 -> AD | CJ9: A | CW9: AD | CX9: C | CY9: B | CZ9: B | DA9: =CZ9*2+4 -> #VALUE!
A10: 4 | B10: ='RELACION ESTUDIANTES - 2022'!B9 -> CUADROS ZEVALLOS ANGELO DAVID | D10: AD | E10: AD | F10: AD | H10: =Q10 -> AD | I10: AD | K10: AD | L10: AD | M10: AD | Q10: =Y10 -> AD | R10: AD | T10: AD | U10: AD | V10: A | W10: AD | Y10: =AL10 -> AD | Z10: AD | AG10: AD | AH10: AD | AI10: AD | AK10: AD | AL10: =AT10 -> AD | AM10: AD | AP10: B | AQ10: AD | AS10: A | AT10: =BC10 -> AD | AU10: A | AW10: A | AX10: AD | AY10: AD | AZ10: A | BC10: =BK10 -> AD | BD10: A | BF10: A | BG10: AD | BH10: AD | BI10: AD | BJ10: A | BK10: =BY10 -> AD | BL10: AD | BS10: A | BT10: AD | BU10: AD | BW10: AD | BX10: A | BY10: =CI10 -> AD | BZ10: A | CB10: AD | CC10: AD | CE10: AD | CF10: AD | CG10: A | CI10: =CW10 -> AD | CJ10: AD | CW10: AD | CX10: B | CY10: AD | CZ10: A | DA10: =CZ10*2+4 -> #VALUE!
A11: 5 | B11: ='RELACION ESTUDIANTES - 2022'!B10 -> GALINDO HERNANDEZ EMERSON FELIPE | D11: AD | E11: A | F11: AD | H11: =Q11 -> AD | I11: AD | K11: AD | L11: AD | M11: AD | Q11: =Y11 -> AD | R11: AD | T11: AD | U11: AD | V11: AD | W11: AD | Y11: =AL11 -> AD | Z11: AD | AG11: AD | AH11: A | AI11: AD | AK11: AD | AL11: =AT11 -> AD | AM11: AD | AP11: AD | AQ11: AD | AS11: AD | AT11: =BC11 -> AD | AU11: AD | AW11: A | AX11: C | AY11: AD | AZ11: AD | BC11: =BK11 -> AD | BD11: B | BF11: AD | BG11: AD | BH11: AD | BI11: AD | BJ11: AD | BK11: =BY11 -> AD | BL11: AD | BS11: AD | BT11: AD | BU11: A | BW11: AD | BX11: AD | BY11: =CI11 -> AD | BZ11: AD | CB11: AD | CC11: AD | CE11: AD | CF11: AD | CG11: AD | CI11: =CW11 -> AD | CJ11: AD | CW11: AD | CX11: A | CY11: AD | CZ11: AD | DA11: =CZ11*2+4 -> #VALUE!
A12: 6 | B12: ='RELACION ESTUDIANTES - 2022'!B11 -> HERNANDEZ ENRIQUEZ JARED MIGUEL | D12: AD | E12: A | F12: AD | H12: =Q12 -> AD | I12: AD | K12: AD | L12: AD | M12: AD | Q12: =Y12 -> AD | R12: AD | T12: AD | U12: AD | V12: AD | W12: AD | Y12: =AL12 -> AD | Z12: AD | AG12: AD | AH12: AD | AI12: AD | AK12: AD | AL12: =AT12 -> AD | AM12: AD | AP12: AD | AQ12: C | AS12: B | AT12: =BC12 -> AD | AU12: B | AW12: A | AX12: AD | AY12: A | AZ12: B | BC12: =BK12 -> AD | BD12: A | BF12: AD | BG12: AD | BH12: AD | BI12: AD | BJ12: B | BK12: =BY12 -> AD | BL12: A | BS12: AD | BT12: AD | BU12: AD | BW12: AD | BX12: B | BY12: =CI12 -> AD | BZ12: A | CB12: A | CC12: A | CE12: AD | CF12: AD | CG12: B | CI12: =CW12 -> AD | CJ12: A | CW12: AD | CX12: C | CY12: AD | CZ12: B | DA12: =CZ12*2+4 -> #VALUE!
A13: 7 | B13: ='RELACION ESTUDIANTES - 2022'!B12 -> HERNANDEZ MUNIVE NICOLAS ERNESTO | D13: AD | E13: AD | F13: AD | H13: =Q13 -> AD | I13: AD | K13: AD | L13: AD | M13: AD | Q13: =Y13 -> AD | R13: AD | T13: AD | U13: A | V13: AD | W13: AD | Y13: =AL13 -> AD | Z13: AD | AG13: AD | AH13: AD | AI13: B | AK13: AD | AL13: =AT13 -> AD | AM13: A | AP13: B | AQ13: AD | AS13: AD | AT13: =BC13 -> AD | AU13: A | AW13: A | AX13: AD | AY13: AD | AZ13: AD | BC13: =BK13 -> AD | BD13: AD | BF13: AD | BG13: AD | BH13: AD | BI13: AD | BJ13: AD | BK13: =BY13 -> AD | BL13: AD | BS13: AD | BT13: AD | BU13: AD | BW13: AD | BX13: AD | BY13: =CI13 -> AD | BZ13: AD | CB13: AD | CC13: AD | CE13: AD | CF13: AD | CG13: AD | CI13: =CW13 -> AD | CJ13: AD | CW13: AD | CX13: A | CY13: AD | CZ13: AD | DA13: =CZ13*2+4 -> #VALUE!
A14: 8 | B14: ='RELACION ESTUDIANTES - 2022'!B13 -> NAVAS GOMEZ BENJAMIN HUMBERTO | D14: A | E14: A | F14: AD | H14: =Q14 -> AD | I14: A | K14: AD | L14: AD | M14: AD | Q14: =Y14 -> AD | R14: AD | T14: AD | U14: AD | V14: AD | W14: AD | Y14: =AL14 -> AD | Z14: AD | AG14: AD | AH14: A | AI14: AD | AK14: AD | AL14: =AT14 -> AD | AM14: AD | AP14: A | AQ14: A | AS14: B | AT14: =BC14 -> AD | AU14: A | AW14: A | AX14: AD | AY14: A | AZ14: B | BC14: =BK14 -> AD | BD14: A | BF14: AD | BG14: B | BH14: A | BI14: AD | BJ14: B | BK14: =BY14 -> AD | BL14: A | BS14: A | BT14: A | BU14: A | BW14: AD | BX14: B | BY14: =CI14 -> AD | BZ14: A | CB14: AD | CC14: AD | CE14: AD | CF14: AD | CG14: B | CI14: =CW14 -> AD | CJ14: A | CW14: AD | CX14: C | CY14: AD | CZ14: B | DA14: =CZ14*2+4 -> #VALUE!
A15: 9 | B15: ='RELACION ESTUDIANTES - 2022'!B14 -> PACHECO ESPILLCO MATIAS DEYAIR | D15: A | E15: AD | F15: A | H15: =Q15 -> AD | I15: A | K15: B | L15: AD | M15: AD | Q15: =Y15 -> AD | R15: A | T15: AD | U15: AD | V15: AD | W15: A | Y15: =AL15 -> AD | Z15: AD | AG15: AD | AH15: AD | AI15: AD | AK15: AD | AL15: =AT15 -> AD | AM15: AD | AP15: B | AQ15: A | AS15: AD | AT15: =BC15 -> AD | AU15: A | AW15: A | AX15: AD | AY15: B | AZ15: AD | BC15: =BK15 -> AD | BD15: A | BF15: A | BG15: AD | BH15: B | BI15: AD | BJ15: AD | BK15: =BY15 -> AD | BL15: A | BS15: AD | BT15: AD | BU15: A | BW15: A | BX15: AD | BY15: =CI15 -> AD | BZ15: A | CB15: B | CC15: A | CE15: A | CF15: AD | CG15: AD | CI15: =CW15 -> AD | CJ15: A | CW15: AD | CX15: A | CY15: AD | CZ15: AD | DA15: =CZ15*2+4 -> #VALUE!
A16: 10 | B16: ='RELACION ESTUDIANTES - 2022'!B15 -> RAMIREZ ESCRIBA JHERCY HUSCIEL | D16: AD | E16: A | F16: C | H16: =Q16 -> AD | I16: A | K16: A | L16: AD | M16: AD | Q16: =Y16 -> AD | R16: AD | T16: C | U16: AD | V16: B | W16: A | Y16: =AL16 -> AD | Z16: B | AG16: AD | AH16: AD | AI16: AD | AK16: AD | AL16: =AT16 -> AD | AM16: AD | AP16: AD | AQ16: AD | AS16: AD | AT16: =BC16 -> AD | AU16: AD | AW16: A | AX16: AD | AY16: C | AZ16: AD | BC16: =BK16 -> AD | BD16: B | BF16: AD | BG16: B | BH16: A | BI16: AD | BJ16: AD | BK16: =BY16 -> AD | BL16: A | BS16: A | BT16: AD | BU16: B | BW16: A | BX16: AD | BY16: =CI16 -> AD | BZ16: A | CB16: AD | CC16: A | CE16: A | CF16: AD | CG16: AD | CI16: =CW16 -> AD | CJ16: A | CW16: AD | CX16: A | CY16: AD | CZ16: AD | DA16: =CZ16*2+4 -> #VALUE!
A17: 11 | B17: ='RELACION ESTUDIANTES - 2022'!B16 -> SANCHEZ SANTIAGO KALEB MOISES | D17: AD | E17: B | F17: A | H17: =Q17 -> AD | I17: A | K17: AD | L17: B | M17: AD | Q17: =Y17 -> AD | R17: A | T17: AD | U17: AD | V17: AD | W17: A | Y17: =AL17 -> AD | Z17: AD | AG17: B | AH17: A | AI17: B | AK17: A | AL17: =AT17 -> AD | AM17: A | AP17: A | AQ17: A | AS17: B | AT17: =BC17 -> AD | AU17: A | AW17: A | AX17: C | AY17: B | AZ17: B | BC17: =BK17 -> AD | BD17: B | BF17: AD | BG17: AD | BH17: A | BI17: A | BJ17: B | BK17: =BY17 -> AD | BL17: A | BS17: A | BT17: A | BU17: B | BW17: A | BX17: B | BY17: =CI17 -> AD | BZ17: A | CB17: AD | CC17: A | CE17: A | CF17: A | CG17: B | CI17: =CW17 -> AD | CJ17: A | CW17: AD | CX17: C | CY17: B | CZ17: B | DA17: =CZ17*2+4 -> #VALUE!
A18: 12 | B18: ='RELACION ESTUDIANTES - 2022'!B17 -> SEGOVIA LICAS DANGELO KENDALL | D18: A | E18: B | F18: A | H18: =Q18 -> AD | I18: A | K18: A | L18: A | M18: A | Q18: =Y18 -> AD | R18: A | T18: AD | U18: AD | V18: AD | W18: A | Y18: =AL18 -> AD | Z18: AD | AG18: B | AH18: A | AI18: AD | AK18: AD | AL18: =AT18 -> AD | AM18: A | AP18: A | AQ18: AD | AS18: B | AT18: =BC18 -> AD | AU18: A | AW18: A | AX18: A | AY18: C | AZ18: B | BC18: =BK18 -> AD | BD18: B | BF18: A | BG18: B | BH18: A | BI18: AD | BJ18: B | BK18: =BY18 -> AD | BL18: A | BS18: C | BT18: A | BU18: B | BW18: A | BX18: B | BY18: =CI18 -> AD | BZ18: B | CB18: A | CC18: A | CE18: A | CF18: AD | CG18: B | CI18: =CW18 -> AD | CJ18: A | CW18: AD | CX18: C | CY18: B | CZ18: B | DA18: =CZ18*2+4 -> #VALUE!
A19: 13 | B19: ='RELACION ESTUDIANTES - 2022'!B18 -> VELARDE GONZALEZ MARCOS MIGUEL | D19: AD | E19: B | F19: A | H19: =Q19 -> AD | I19: A | K19: A | L19: B | M19: B | Q19: =Y19 -> AD | R19: B | T19: AD | U19: AD | V19: B | W19: C | Y19: =AL19 -> AD | Z19: B | AG19: AD | AH19: A | AI19: C | AK19: A | AL19: =AT19 -> AD | AM19: B | AP19: B | AQ19: C | AS19: B | AT19: =BC19 -> AD | AU19: B | AW19: B | AX19: A | AY19: B | AZ19: B | BC19: =BK19 -> AD | BD19: B | BF19: A | BG19: A | BH19: A | BI19: A | BJ19: B | BK19: =BY19 -> AD | BL19: A | BS19: A | BT19: B | BU19: B | BW19: C | BX19: B | BY19: =CI19 -> AD | BZ19: B | CB19: B | CC19: A | CE19: C | CF19: A | CG19: B | CI19: =CW19 -> AD | CJ19: B | CW19: AD | CX19: C | CY19: AD | CZ19: B | DA19: =CZ19*2+4 -> #VALUE!
A20: 14 | B20: ='RELACION ESTUDIANTES - 2022'!B19 -> YARCURI CRISOSTOMO JUAN DIEGO | D20: B | E20: A | F20: A | H20: =Q20 -> AD | I20: A | K20: B | L20: B | M20: B | Q20: =Y20 -> AD | R20: B | T20: A | U20: AD | V20: AD | W20: B | Y20: =AL20 -> AD | Z20: A | AG20: AD | AH20: AD | AI20: B | AK20: A | AL20: =AT20 -> AD | AM20: A | AP20: B | AQ20: AD | AS20: B | AT20: =BC20 -> AD | AU20: B | AW20: B | AX20: C | AY20: B | AZ20: B | BC20: =BK20 -> AD | BD20: B | BF20: A | BG20: AD | BH20: B | BI20: A | BJ20: B | BK20: =BY20 -> AD | BL20: A | BS20: A | BT20: AD | BU20: A | BW20: B | BX20: B | BY20: =CI20 -> AD | BZ20: A | CB20: B | CC20: A | CE20: B | CF20: A | CG20: B | CI20: =CW20 -> AD | CJ20: A | CW20: AD | CX20: C | CY20: AD | CZ20: B | DA20: =CZ20*2+4 -> #VALUE!
A21: 15 | Y21: =AL21 -> 0 | AL21: =AT21 -> 0 | AT21: =BC21 -> 0 | BC21: =BK21 -> 0 | BK21: =BY21 -> 0 | BY21: =CI21 -> 0 | CI21: =CW21 -> 0 | CW21: 0 | CZ21: =COUNTIF(AA21:CT21,"OK") -> 0 | DA21: =CZ21*2+4 -> 4
A22: 16 | Y22: =AL22 -> 0 | AL22: =AT22 -> 0 | AT22: =BC22 -> 0 | BC22: =BK22 -> 0 | BK22: =BY22 -> 0 | BY22: =CI22 -> 0 | CI22: =CW22 -> 0 | CW22: 0 | CZ22: =COUNTIF(AA22:CT22,"OK") -> 0
A23: 17 | Y23: =AL23 -> 0 | AL23: =AT23 -> 0 | AT23: =BC23 -> 0 | AZ23: X5 | BC23: =BK23 -> 0 | BK23: =BY23 -> 0 | BY23: =CI23 -> 0 | CI23: =CW23 -> 0 | CW23: 0 | CZ23: =COUNTIF(AA23:CT23,"OK") -> 0
A24: 18 | H24: =Q24 -> 0 | Q24: =Y24 -> 0 | Y24: =AL24 -> 0 | AL24: =AT24 -> 0 | AT24: =BC24 -> 0 | BC24: =BK24 -> 0 | BK24: =BY24 -> 0 | BY24: =CI24 -> 0 | CI24: =CW24 -> 0 | CW24: 0 | CZ24: =COUNTIF(AA24:CT24,"OK") -> 0 | DA24: =CZ24*2+4 -> 4
A25: 19 | AN25: =IF(AO25>=18,"AD",IF(AO25>=15,"A",IF(AO25>=11,"B"," "))) | BE25: =IF(BF25>=18,"AD",IF(BF25>=15,"A",IF(BF25>=11,"B"," "))) | CZ25: =COUNTIF(AA25:CT25,"OK") -> 0 | DA25: =CZ25*2+4 -> 4
A26: 20 | AN26: =IF(AO26>=18,"AD",IF(AO26>=15,"A",IF(AO26>=11,"B"," "))) | AU26: =ROUND(AVERAGE(AO26:AT26),0) -> #DIV/0! | AV26: =IF(AW26>=18,"AD",IF(AW26>=15,"A",IF(AW26>=11,"B"," "))) | BD26: =ROUND(AVERAGE(AW26:BC26),0) -> #DIV/0! | BE26: =IF(BF26>=18,"AD",IF(BF26>=15,"A",IF(BF26>=11,"B"," "))) | BR26: =IF(BS26>=18,"AD",IF(BS26>=15,"A",IF(BS26>=11,"B"," "))) | CZ26: =COUNTIF(AA26:CT26,"OK") -> 0 | DA26: =CZ26*2+4 -> 4
A27: 21 | AN27: =IF(AO27>=18,"AD",IF(AO27>=15,"A",IF(AO27>=11,"B"," "))) | AU27: =ROUND(AVERAGE(AO27:AT27),0) -> #DIV/0! | AV27: =IF(AW27>=18,"AD",IF(AW27>=15,"A",IF(AW27>=11,"B"," "))) | BD27: =ROUND(AVERAGE(AW27:BC27),0) -> #DIV/0! | BE27: =IF(BF27>=18,"AD",IF(BF27>=15,"A",IF(BF27>=11,"B"," "))) | BR27: =IF(BS27>=18,"AD",IF(BS27>=15,"A",IF(BS27>=11,"B"," "))) | BZ27: =ROUND(AVERAGE(BS27:BY27),0) -> #DIV/0! | CA27: =IF(CD27>=18,"AD",IF(CD27>=15,"A",IF(CD27>=11,"B"," "))) | CJ27: =ROUND(AVERAGE(CD27:CI27),0) -> #DIV/0! | CZ27: =COUNTIF(AA27:CT27,"OK") -> 0 | DA27: =CZ27*2+4 -> 4
A28: 22 | AM28: =ROUND(AVERAGE(AG28:AL28),0) -> #DIV/0! | AN28: =IF(AO28>=18,"AD",IF(AO28>=15,"A",IF(AO28>=11,"B"," "))) | AU28: =ROUND(AVERAGE(AO28:AT28),0) -> #DIV/0! | AV28: =IF(AW28>=18,"AD",IF(AW28>=15,"A",IF(AW28>=11,"B"," "))) | BD28: =ROUND(AVERAGE(AW28:BC28),0) -> #DIV/0! | BE28: =IF(BF28>=18,"AD",IF(BF28>=15,"A",IF(BF28>=11,"B"," "))) | BL28: =ROUND(AVERAGE(BF28:BK28),0) -> #DIV/0! | BR28: =IF(BS28>=18,"AD",IF(BS28>=15,"A",IF(BS28>=11,"B"," "))) | BZ28: =ROUND(AVERAGE(BS28:BY28),0) -> #DIV/0! | CA28: =IF(CD28>=18,"AD",IF(CD28>=15,"A",IF(CD28>=11,"B"," "))) | CJ28: =ROUND(AVERAGE(CD28:CI28),0) -> #DIV/0! | CZ28: =COUNTIF(AA28:CT28,"OK") -> 0 | DA28: =CZ28*2+4 -> 4
A29: 23 | R29: =ROUND(AVERAGE(P29:Q29),0) -> #DIV/0! | AM29: =ROUND(AVERAGE(AG29:AL29),0) -> #DIV/0! | AN29: =IF(AO29>=18,"AD",IF(AO29>=15,"A",IF(AO29>=11,"B"," "))) | AU29: =ROUND(AVERAGE(AO29:AT29),0) -> #DIV/0! | AV29: =IF(AW29>=18,"AD",IF(AW29>=15,"A",IF(AW29>=11,"B"," "))) | BD29: =ROUND(AVERAGE(AW29:BC29),0) -> #DIV/0! | BE29: =IF(BF29>=18,"AD",IF(BF29>=15,"A",IF(BF29>=11,"B"," "))) | BL29: =ROUND(AVERAGE(BF29:BK29),0) -> #DIV/0! | BR29: =IF(BS29>=18,"AD",IF(BS29>=15,"A",IF(BS29>=11,"B"," "))) | BZ29: =ROUND(AVERAGE(BS29:BY29),0) -> #DIV/0! | CA29: =IF(CD29>=18,"AD",IF(CD29>=15,"A",IF(CD29>=11,"B"," "))) | CJ29: =ROUND(AVERAGE(CD29:CI29),0) -> #DIV/0! | CZ29: =COUNTIF(AA29:CT29,"OK") -> 0 | DA29: =CZ29*2+4 -> 4
A30: 24 | R30: =ROUND(AVERAGE(P30:Q30),0) -> #DIV/0! | Z30: =ROUND(AVERAGE(X30:Y30),0) -> #DIV/0! | AM30: =ROUND(AVERAGE(AG30:AL30),0) -> #DIV/0! | AN30: =IF(AO30>=18,"AD",IF(AO30>=15,"A",IF(AO30>=11,"B"," "))) | AU30: =ROUND(AVERAGE(AO30:AT30),0) -> #DIV/0! | AV30: =IF(AW30>=18,"AD",IF(AW30>=15,"A",IF(AW30>=11,"B"," "))) | BD30: =ROUND(AVERAGE(AW30:BC30),0) -> #DIV/0! | BE30: =IF(BF30>=18,"AD",IF(BF30>=15,"A",IF(BF30>=11,"B"," "))) | BL30: =ROUND(AVERAGE(BF30:BK30),0) -> #DIV/0! | BR30: =IF(BS30>=18,"AD",IF(BS30>=15,"A",IF(BS30>=11,"B"," "))) | BZ30: =ROUND(AVERAGE(BS30:BY30),0) -> #DIV/0! | CA30: =IF(CD30>=18,"AD",IF(CD30>=15,"A",IF(CD30>=11,"B"," "))) | CJ30: =ROUND(AVERAGE(CD30:CI30),0) -> #DIV/0! | CZ30: =COUNTIF(AA30:CT30,"OK") -> 0 | DA30: =CZ30*2+4 -> 4
A31: 25 | R31: =ROUND(AVERAGE(P31:Q31),0) -> #DIV/0! | Z31: =ROUND(AVERAGE(X31:Y31),0) -> #DIV/0! | AM31: =ROUND(AVERAGE(AG31:AL31),0) -> #DIV/0! | AN31: =IF(AO31>=18,"AD",IF(AO31>=15,"A",IF(AO31>=11,"B"," "))) | AU31: =ROUND(AVERAGE(AO31:AT31),0) -> #DIV/0! | AV31: =IF(AW31>=18,"AD",IF(AW31>=15,"A",IF(AW31>=11,"B"," "))) | BD31: =ROUND(AVERAGE(AW31:BC31),0) -> #DIV/0! | BE31: =IF(BF31>=18,"AD",IF(BF31>=15,"A",IF(BF31>=11,"B"," "))) | BL31: =ROUND(AVERAGE(BF31:BK31),0) -> #DIV/0! | BR31: =IF(BS31>=18,"AD",IF(BS31>=15,"A",IF(BS31>=11,"B"," "))) | BZ31: =ROUND(AVERAGE(BS31:BY31),0) -> #DIV/0! | CA31: =IF(CD31>=18,"AD",IF(CD31>=15,"A",IF(CD31>=11,"B"," "))) | CJ31: =ROUND(AVERAGE(CD31:CI31),0) -> #DIV/0! | CZ31: =COUNTIF(AA31:CT31,"OK") -> 0 | DA31: =CZ31*2+4 -> 4
A32: 26 | R32: =ROUND(AVERAGE(P32:Q32),0) -> #DIV/0! | Z32: =ROUND(AVERAGE(X32:Y32),0) -> #DIV/0! | AM32: =ROUND(AVERAGE(AG32:AL32),0) -> #DIV/0! | AN32: =IF(AO32>=18,"AD",IF(AO32>=15,"A",IF(AO32>=11,"B"," "))) | AU32: =ROUND(AVERAGE(AO32:AT32),0) -> #DIV/0! | AV32: =IF(AW32>=18,"AD",IF(AW32>=15,"A",IF(AW32>=11,"B"," "))) | BD32: =ROUND(AVERAGE(AW32:BC32),0) -> #DIV/0! | BE32: =IF(BF32>=18,"AD",IF(BF32>=15,"A",IF(BF32>=11,"B"," "))) | BL32: =ROUND(AVERAGE(BF32:BK32),0) -> #DIV/0! | BR32: =IF(BS32>=18,"AD",IF(BS32>=15,"A",IF(BS32>=11,"B"," "))) | BZ32: =ROUND(AVERAGE(BS32:BY32),0) -> #DIV/0! | CA32: =IF(CD32>=18,"AD",IF(CD32>=15,"A",IF(CD32>=11,"B"," "))) | CJ32: =ROUND(AVERAGE(CD32:CI32),0) -> #DIV/0! | CZ32: =COUNTIF(AA32:CT32,"OK") -> 0 | DA32: =CZ32*2+4 -> 4
A33: 27 | R33: =ROUND(AVERAGE(P33:Q33),0) -> #DIV/0! | Z33: =ROUND(AVERAGE(X33:Y33),0) -> #DIV/0! | AM33: =ROUND(AVERAGE(AG33:AL33),0) -> #DIV/0! | AN33: =IF(AO33>=18,"AD",IF(AO33>=15,"A",IF(AO33>=11,"B"," "))) | AU33: =ROUND(AVERAGE(AO33:AT33),0) -> #DIV/0! | AV33: =IF(AW33>=18,"AD",IF(AW33>=15,"A",IF(AW33>=11,"B"," "))) | BD33: =ROUND(AVERAGE(AW33:BC33),0) -> #DIV/0! | BE33: =IF(BF33>=18,"AD",IF(BF33>=15,"A",IF(BF33>=11,"B"," "))) | BL33: =ROUND(AVERAGE(BF33:BK33),0) -> #DIV/0! | BR33: =IF(BS33>=18,"AD",IF(BS33>=15,"A",IF(BS33>=11,"B"," "))) | BZ33: =ROUND(AVERAGE(BS33:BY33),0) -> #DIV/0! | CA33: =IF(CD33>=18,"AD",IF(CD33>=15,"A",IF(CD33>=11,"B"," "))) | CJ33: =ROUND(AVERAGE(CD33:CI33),0) -> #DIV/0! | CZ33: =COUNTIF(AA33:CT33,"OK") -> 0 | DA33: =CZ33*2+4 -> 4
A34: 28 | I34: =ROUND(AVERAGE(D34:H34),0) -> #DIV/0! | R34: =ROUND(AVERAGE(P34:Q34),0) -> #DIV/0! | Z34: =ROUND(AVERAGE(X34:Y34),0) -> #DIV/0! | AM34: =ROUND(AVERAGE(AG34:AL34),0) -> #DIV/0! | AN34: =IF(AO34>=18,"AD",IF(AO34>=15,"A",IF(AO34>=11,"B"," "))) | AU34: =ROUND(AVERAGE(AO34:AT34),0) -> #DIV/0! | AV34: =IF(AW34>=18,"AD",IF(AW34>=15,"A",IF(AW34>=11,"B"," "))) | BD34: =ROUND(AVERAGE(AW34:BC34),0) -> #DIV/0! | BE34: =IF(BF34>=18,"AD",IF(BF34>=15,"A",IF(BF34>=11,"B"," "))) | BL34: =ROUND(AVERAGE(BF34:BK34),0) -> #DIV/0! | BR34: =IF(BS34>=18,"AD",IF(BS34>=15,"A",IF(BS34>=11,"B"," "))) | BZ34: =ROUND(AVERAGE(BS34:BY34),0) -> #DIV/0! | CA34: =IF(CD34>=18,"AD",IF(CD34>=15,"A",IF(CD34>=11,"B"," "))) | CJ34: =ROUND(AVERAGE(CD34:CI34),0) -> #DIV/0! | CZ34: =COUNTIF(AA34:CT34,"OK") -> 0 | DA34: =CZ34*2+4 -> 4
A35: 29 | I35: =ROUND(AVERAGE(D35:H35),0) -> #DIV/0! | R35: =ROUND(AVERAGE(P35:Q35),0) -> #DIV/0! | Z35: =ROUND(AVERAGE(X35:Y35),0) -> #DIV/0! | AM35: =ROUND(AVERAGE(AG35:AL35),0) -> #DIV/0! | AN35: =IF(AO35>=18,"AD",IF(AO35>=15,"A",IF(AO35>=11,"B"," "))) | AU35: =ROUND(AVERAGE(AO35:AT35),0) -> #DIV/0! | AV35: =IF(AW35>=18,"AD",IF(AW35>=15,"A",IF(AW35>=11,"B"," "))) | BD35: =ROUND(AVERAGE(AW35:BC35),0) -> #DIV/0! | BE35: =IF(BF35>=18,"AD",IF(BF35>=15,"A",IF(BF35>=11,"B"," "))) | BL35: =ROUND(AVERAGE(BF35:BK35),0) -> #DIV/0! | BR35: =IF(BS35>=18,"AD",IF(BS35>=15,"A",IF(BS35>=11,"B"," "))) | BZ35: =ROUND(AVERAGE(BS35:BY35),0) -> #DIV/0! | CA35: =IF(CD35>=18,"AD",IF(CD35>=15,"A",IF(CD35>=11,"B"," "))) | CJ35: =ROUND(AVERAGE(CD35:CI35),0) -> #DIV/0! | CZ35: =COUNTIF(AA35:CT35,"OK") -> 0 | DA35: =CZ35*2+4 -> 4
A36: 30 | I36: =ROUND(AVERAGE(D36:H36),0) -> #DIV/0! | R36: =ROUND(AVERAGE(P36:Q36),0) -> #DIV/0! | Z36: =ROUND(AVERAGE(X36:Y36),0) -> #DIV/0! | AM36: =ROUND(AVERAGE(AG36:AL36),0) -> #DIV/0! | AN36: =IF(AO36>=18,"AD",IF(AO36>=15,"A",IF(AO36>=11,"B"," "))) | AU36: =ROUND(AVERAGE(AO36:AT36),0) -> #DIV/0! | AV36: =IF(AW36>=18,"AD",IF(AW36>=15,"A",IF(AW36>=11,"B"," "))) | BD36: =ROUND(AVERAGE(AW36:BC36),0) -> #DIV/0! | BE36: =IF(BF36>=18,"AD",IF(BF36>=15,"A",IF(BF36>=11,"B"," "))) | BL36: =ROUND(AVERAGE(BF36:BK36),0) -> #DIV/0! | BR36: =IF(BS36>=18,"AD",IF(BS36>=15,"A",IF(BS36>=11,"B"," "))) | BZ36: =ROUND(AVERAGE(BS36:BY36),0) -> #DIV/0! | CA36: =IF(CD36>=18,"AD",IF(CD36>=15,"A",IF(CD36>=11,"B"," "))) | CJ36: =ROUND(AVERAGE(CD36:CI36),0) -> #DIV/0! | CZ36: =COUNTIF(AA36:CT36,"OK") -> 0
A37: 31 | AN37: =IF(AO37>=18,"AD",IF(AO37>=15,"A",IF(AO37>=11,"B"," "))) | AU37: =ROUND(AVERAGE(AO37:AT37),0) -> #DIV/0! | AV37: =IF(AW37>=18,"AD",IF(AW37>=15,"A",IF(AW37>=11,"B"," "))) | BR37: =IF(BS37>=18,"AD",IF(BS37>=15,"A",IF(BS37>=11,"B"," ")))
A38: 32 | AO38: AeC | AP38: AeC | AQ38: P-C | AR38: AUDI | AY38: P-C
A39: 33 | AO39: PRO | AP39: EVA | AQ39: PRO | AR39: PRO | AY39: REC
A40: 34 | AP40: PRO | AQ40: CLASS | AY40: NAT
A41: 35
A42: 36
...

Sheet 3RO-D-1B-FINAL
A1: REGISTRO AUXILIAR DE EDUCACIÓN PARA EL TRABAJO - ELECTRONICA - 2025 -- 2º BIMESTRE -- 3RO D
A2: Nº DE ORDEN | C2: I. E. | E2: COMPETENCIA: GESTIONA PROYECTOS DE EMPRENDIMIENTO ECONOMICO Y/O SOCIAL | AH2: Promedio de Capacidades y Actitudes | AP2: PROMEDIO BIMESTRAL
C3: "SAN LUIS GONZAGA" | E3: CREA PROPUESTA DE VALOR | J3: APLICA HABILIDADES Y TECNICAS | O3: TRABAJA COOPERATIVAMENTE PARA LOGRAR OBJETIVOS Y METAS | S3: EVALUA LOS RESULTADOS DEL PROYECTO | X3: SE DESEMVUELVE EN ENTORNOS VIRTUALES GENERDAS POR LAS TIC | AC3: GESTIONA SU APRENDIZAJE DE MAERA AUTONOMA | AH3: PC-1 | AI3: PC-2 | AJ3: PC-3 | AK3: PC-4 | AM3: PC-5 | AN3: PC-6 | AR3: Se desenvuelve en entornos virtuales generados por las TIC
B4: ESPECIALIDAD: ELECTRONICA | E4: Crea propuestas de valor de un proyecto de meprendimiento economico o social orientado a la especialidad para el concuros Crea y Emprende; asi mismo conoce y cumple las normas de convivencia y seguridad y riesgo electrico | F4: Crea propuestas de valor que apoyen su economia familira siguiendo los pasos y reconmendaciones de Design Thinking aplicando fundamento de electronica mediante proyectos aplicativos | G4: Planifica su desarrollo de portafolio para el concuros interno de Crea y Emprende realizando actividades varias: Organiza el equipo de trabajo, implementa un diagrama de Gantt, etc. | I4: PROMEDIO C-1 | J4: Aplica e implementa acciones que le ayuden a reconocer circuitos y sistemas electronicos de un robot seguidor de linea o de luz | K4: Ejecuta actividades donde identifique las Leyes y principos de la electronica y circuitos electricos y electronicos básicos y los aplique en su proyecto electronico un juguete robotico con dispositivos electronicos | L4: Implementa el prototipo del sistemas electronico de un robot seguidor de linea o de luz. | N4: PROMEDIO C-2 | O4: Trabaja cooperativamente recombinado sus roles y responsabilidades individuales para el logro de la competencia | P4: Organiza su area de trabajo y autonomia de trabajo para su adecuado desarrollo de habilidades tecnicas en el taller | R4: PROMEDIO C-3 | S4: Implementa tecnicas (malla receptora) optimamente para evaluar su proptotipo y proyecto de meprendimiento | T4: Incorpora mejoras innovadoras y creativas en el proyecto basico de emprendimiento orientado a la especialidad de EPT. | V4: PROMEDIO C-4 | X4: Personaliza entornos virtuales seleccionandolos, modificandolos y optimizandolos de acuerdo a sus intereses y actividades | Y4: Gestiona información del entorno virtual organizandolo y sistematizandolo considerando diferentes procedimientos y formas digitalesde manera etica y pertinenete | Z4: Interactua en entornos virtuales de manera colaborativa para comunicarse, construir y mantener vinculos según su edad y sus intereses de m,anera segura y coherente | AA4: Crea objetos virtuales en diversos formatos de manera digital siguiendo procesos de mejora y retroalimentación desde su contexto y vida cotidiana | AB4: PROMEDIO C-5 | AC4: Define metas de aprendizaje en funcion a sus necesidades para resolver diferentes tareas dadas a fin de logras metas trazadas | AD4: Organiza acciones estrategicas para alcanzar sus metas de manra eficiente estableciendo mecanismos para alcanzar sus temas de aprendizaje | AE4: Monitorea y ajusta su desempeño durante el proceso de aprendizaje verificando su avance en relacion a su metas de aprendizaje de manera pertinente | AF4: PROMEDIO C-6
B5: GRADO Y SECCIÓN: 3 "D"
B6: BIMESTRE: II
B7: PROFESOR (A): Julio César
B8: SORIA QUISPE
B9: APELLIDOS Y NOMBRES
A11: 01 | B11: ='3RO-D'!B7 -> CASAVILCA ACOSTA YZUHAIM HUGO ALBERTO | E11: AD | F11: A | G11: AD | I11: AD | J11: AD | K11: AD | L11: AD | N11: AD | O11: AD | P11: =N11 -> AD | R11: AD | S11: AD | T11: AD | V11: AD | X11: A | Y11: A | Z11: B | AA11: B | AB11: A | AC11: A | AD11: A | AE11: B | AF11: A | AH11: =I11 -> AD | AI11: =N11 -> AD | AJ11: =R11 -> AD | AK11: =V11 -> AD | AM11: =AB11 -> A | AN11: =AF11 -> A | AP11: AD
A12: 02 | B12: ='3RO-D'!B8 -> CASTRO VARGAS JHORDAN ANDREE WILLIAN | E12: AD | F12: A | G12: A | I12: A | J12: B | K12: A | L12: AD | N12: A | O12: AD | P12: =N12 -> A | R12: A | S12: A | T12: A | V12: A | X12: A | Y12: A | Z12: A | AA12: B | AB12: A | AC12: B | AD12: B | AE12: B | AF12: B | AH12: =I12 -> A | AI12: =N12 -> A | AJ12: =R12 -> A | AK12: =V12 -> A | AM12: =AB12 -> A | AN12: =AF12 -> B | AP12: A | AS12: RESUMEN - Iv BIMESTRE
A13: 03 | B13: ='3RO-D'!B9 -> CONDE GAMBOA JHONATAN RODRIGO | E13: AD | F13: A | G13: A | I13: A | J13: B | K13: B | L13: A | N13: B | O13: A | P13: =N13 -> B | R13: B | S13: AD | T13: A | V13: A | X13: A | Y13: A | Z13: A | AA13: B | AB13: A | AC13: B | AD13: B | AE13: B | AF13: B | AH13: =I13 -> A | AI13: =N13 -> B | AJ13: =R13 -> B | AK13: =V13 -> A | AM13: =AB13 -> A | AN13: =AF13 -> B | AP13: A | AX13: Nº | AZ13: %
A14: 04 | B14: ='3RO-D'!B10 -> CUADROS ZEVALLOS ANGELO DAVID | E14: AD | F14: AD | G14: AD | I14: AD | J14: A | K14: A | L14: AD | N14: A | O14: A | P14: =N14 -> A | R14: A | S14: AD | T14: AD | V14: AD | X14: A | Y14: A | Z14: A | AA14: B | AB14: A | AC14: A | AD14: A | AE14: B | AF14: A | AH14: =I14 -> AD | AI14: =N14 -> A | AJ14: =R14 -> A | AK14: =V14 -> AD | AM14: =AB14 -> A | AN14: =AF14 -> A | AP14: AD | AS14: EVALUADOS | AX14: =SUM(AX15:AX22) -> 14 | AZ14: =SUM(AZ15:AZ22) -> 100 | BB14: =SUM(BB15:BB22) -> 100
A15: 05 | B15: ='3RO-D'!B11 -> GALINDO HERNANDEZ EMERSON FELIPE | E15: AD | F15: AD | G15: AD | I15: AD | J15: AD | K15: B | L15: AD | N15: A | O15: AD | P15: =N15 -> A | R15: A | S15: AD | T15: AD | V15: AD | X15: A | Y15: A | Z15: A | AA15: B | AB15: A | AC15: A | AD15: A | AE15: B | AF15: A | AH15: =I15 -> AD | AI15: =N15 -> A | AJ15: =R15 -> A | AK15: =V15 -> AD | AM15: =AB15 -> A | AN15: A | AP15: AD | AR15: RETIRADO POR INASISTENCIA CON MAS DE 80 % -- RD ---- | AS15: AD | AX15: =COUNTIF($AP$11:$AP$24,"AD") -> 4 | AZ15: =AX15*100/$AX$14 -> 28.571429 | BB15: 0
A16: 06 | B16: ='3RO-D'!B12 -> HERNANDEZ ENRIQUEZ JARED MIGUEL | E16: AD | F16: AD | G16: AD | I16: AD | J16: B | K16: A | L16: A | N16: A | O16: A | P16: =N16 -> A | R16: A | S16: AD | T16: A | V16: A | X16: A | Y16: A | Z16: A | AA16: B | AB16: A | AC16: B | AD16: B | AE16: B | AF16: B | AH16: =I16 -> AD | AI16: =N16 -> A | AJ16: =R16 -> A | AK16: =V16 -> A | AM16: =AB16 -> A | AN16: =AF16 -> B | AP16: A | AS16: A | AX16: =COUNTIF($AP$11:$AP$24,"A") -> 9 | AZ16: =AX16*100/$AX$14 -> 64.285714 | BB16: 79
A17: 07 | B17: ='3RO-D'!B13 -> HERNANDEZ MUNIVE NICOLAS ERNESTO | E17: AD | F17: A | G17: AD | I17: AD | J17: A | K17: AD | L17: AD | N17: AD | O17: AD | P17: =N17 -> AD | R17: AD | S17: AD | T17: AD | V17: AD | X17: A | Y17: A | Z17: A | AA17: B | AB17: A | AC17: A | AD17: A | AE17: B | AF17: A | AH17: =I17 -> AD | AI17: =N17 -> AD | AJ17: =R17 -> AD | AK17: =V17 -> AD | AM17: =AB17 -> A | AN17: =AF17 -> A | AP17: AD | AR17: RETIRADO POR INASISTENCIA CON MAS DE 80 % -- RD ---- | AS17: B | AX17: =COUNTIF($AP$11:$AP$24,"B") -> 1 | AZ17: =AX17*100/$AX$14 -> 7.1428571 | BB17: 21
A18: 08 | B18: ='3RO-D'!B14 -> NAVAS GOMEZ BENJAMIN HUMBERTO | E18: AD | F18: AD | G18: A | I18: AD | J18: A | K18: A | L18: A | N18: A | O18: A | P18: =N18 -> A | R18: A | S18: AD | T18: A | V18: A | X18: A | Y18: A | Z18: A | AA18: A | AB18: A | AC18: B | AD18: B | AE18: B | AF18: B | AH18: =I18 -> AD | AI18: =N18 -> A | AJ18: =R18 -> A | AK18: =V18 -> A | AM18: =AB18 -> A | AN18: =AF18 -> B | AP18: A | AS18: C | AX18: =COUNTIF($AP$11:$AP$24,"C") -> 0 | AZ18: =AX18*100/$AX$14 -> 0
A19: 09 | B19: ='3RO-D'!B15 -> PACHECO ESPILLCO MATIAS DEYAIR | E19: AD | F19: AD | G19: A | I19: AD | J19: A | K19: A | L19: A | N19: A | O19: A | P19: =N19 -> A | R19: A | S19: A | T19: A | V19: A | X19: A | Y19: A | Z19: A | AA19: B | AB19: A | AC19: B | AD19: B | AE19: B | AF19: B | AH19: =I19 -> AD | AI19: =N19 -> A | AJ19: =R19 -> A | AK19: =V19 -> A | AM19: =AB19 -> A | AN19: =AF19 -> B | AP19: A | AS19: NO ASISTEN | AX19: 0 | AZ19: =AX19*100/$AX$14 -> 0 | BB19: 0
A20: 10 | B20: ='3RO-D'!B16 -> RAMIREZ ESCRIBA JHERCY HUSCIEL | E20: B | F20: AD | G20: A | I20: A | J20: AD | K20: B | L20: A | N20: A | O20: A | P20: =N20 -> A | R20: A | S20: AD | T20: A | V20: A | X20: A | Y20: A | Z20: A | AA20: B | AB20: A | AC20: A | AD20: A | AE20: B | AF20: A | AH20: =I20 -> A | AI20: =N20 -> A | AJ20: =R20 -> A | AK20: =V20 -> A | AM20: =AB20 -> A | AN20: B | AP20: A | AS20: EXO | AX20: 0 | AZ20: =AX20*100/$AX$14 -> 0
A21: 11 | B21: ='3RO-D'!B17 -> SANCHEZ SANTIAGO KALEB MOISES | E21: AD | F21: A | G21: A | I21: A | J21: A | K21: B | L21: A | N21: A | O21: A | P21: =N21 -> A | R21: A | S21: A | T21: A | V21: A | X21: A | Y21: A | Z21: B | AA21: B | AB21: A | AC21: B | AD21: B | AE21: B | AF21: B | AH21: =I21 -> A | AI21: =N21 -> A | AJ21: =R21 -> A | AK21: =V21 -> A | AM21: A | AN21: =AF21 -> B | AP21: A | AS21: TRASLAD. (T) | AX21: 0 | AZ21: =AX21*100/$AX$14 -> 0
A22: 12 | B22: ='3RO-D'!B18 -> SEGOVIA LICAS DANGELO KENDALL | E22: AD | F22: A | G22: A | I22: A | J22: A | K22: B | L22: A | N22: A | O22: B | P22: =N22 -> A | R22: B | S22: A | T22: A | V22: A | X22: A | Y22: A | Z22: B | AA22: B | AB22: A | AC22: B | AD22: B | AE22: B | AF22: B | AH22: =I22 -> A | AI22: =N22 -> A | AJ22: =R22 -> B | AK22: =V22 -> A | AM22: A | AN22: =AF22 -> B | AP22: A | AS22: RETIRAD. (R) | AX22: 0 | AZ22: =AX22*100/$AX$14 -> 0
A23: 13 | B23: ='3RO-D'!B19 -> VELARDE GONZALEZ MARCOS MIGUEL | E23: B | F23: B | G23: A | I23: B | J23: B | K23: B | L23: A | N23: B | O23: B | P23: =N23 -> B | R23: B | S23: B | T23: B | V23: B | X23: B | Y23: B | Z23: B | AA23: B | AB23: B | AC23: B | AD23: B | AE23: B | AF23: B | AH23: =I23 -> B | AI23: =N23 -> B | AJ23: =R23 -> B | AK23: =V23 -> B | AM23: =AB23 -> B | AN23: =AF23 -> B | AP23: B
A24: 14 | B24: ='3RO-D'!B20 -> YARCURI CRISOSTOMO JUAN DIEGO | E24: A | F24: A | G24: A | I24: A | J24: B | K24: B | L24: A | N24: B | O24: A | P24: =N24 -> B | R24: B | S24: B | T24: A | V24: A | X24: A | Y24: A | Z24: B | AA24: B | AB24: A | AC24: B | AD24: B | AE24: B | AF24: B | AH24: =I24 -> A | AI24: =N24 -> B | AJ24: =R24 -> B | AK24: =V24 -> A | AM24: =AB24 -> A | AN24: =AF24 -> B | AP24: A
A25: 15 | P25: =N25 -> 0 | AZ25: =SUM(AZ15:AZ22) -> 100
A26: 16 | P26: =N26 -> 0 | AT26: AD | AU26: =COUNTIF(AP11:AP28,"AD") -> 4
A27: 17 | P27: =N27 -> 0 | AT27: A | AU27: =COUNTIF(AP11:AP28,"A") -> 9
A28: 18 | P28: =N28 -> 0 | AT28: B | AU28: =COUNTIF(AP11:AP28,"B") -> 1
A29: 19 | P29: =N29 -> 0 | AT29: C | AU29: =COUNTIF(AP11:AP28,"C") -> 0
A30: 20 | P30: =N30 -> 0
A31: 21 | P31: =N31 -> 0 | AU31: =SUM(AU26:AU29) -> 14
A32: 22 | P32: =N32 -> 0
A33: 23 | P33: =N33 -> 0
A34: 24 | P34: =N34 -> 0
A35: 25 | P35: =N35 -> 0
A36: 26 | P36: =N36 -> 0
A37: 27 | P37: =N37 -> 0
A38: 28 | P38: =N38 -> 0
A39: 29 | P39: =N39 -> 0
A40: 30 | P40: =N40 -> 0
A41: 31 | P41: =N41 -> 0
...

Sheet 5TO-I
B2: REGISTRO AUXILIAR 2025 - 5TO GRADO
B4: 5° "I" | C4: MES DE MAYO AREA DE EPT - ACCIONES REALIZADAS Y SEGUIMIENTO DE ESTUDIANTES | R4: MES DE JUNIO AREA DE EPT - ACCIONES REALIZADAS Y SEGUIMIENTO DE ESTUDIANTES | BW4: MES DE JULIO AREA DE EPT - ACCIONES REALIZADAS Y SEGUIMIENTO DE ESTUDIANTES
A5: N° | B5: APELLIDOS Y NOMBRES | C5: SEM 11 | I5: G | J5: SEM 12 | Q5: S | R5: SEM 13 | AB5: E | AC5: ASIST. | AH5: SEM 14 | AP5: F | AQ5: SEM 15 | AY5: J | AZ5: SEM 16 | BI5: K | BJ5: SEM 17 | BR5: L | BS5: ASIST. | BX5: SEM 18 | CI5: O | CJ5: SEM 19 | CS5: T | CX5: SEM 20 | DE5: ASIST
D6: =K6-7 -> 45804 | E6: =D6+2 -> 45806 | F6: =D6+1 -> 45805 | G6: PROYEC | H6: ASIST | I6: PROM | K6: 45811 | L6: =K6+2 -> 45813 | M6: =K6+3 -> 45814 | N6: PROYEC | O6: ZENER | P6: ASIST | Q6: PROM | S6: =K6+7 -> 45818 | T6: =S6+2 -> 45820 | U6: =S6+3 -> 45821 | V6: PRACT-01 | W6: PRACT-01 | X6: PRAC-02 | Y6: PRAC-02 | Z6: PRACT-03 | AA6: ASIST | AB6: PROM | AI6: =S6+7 -> 45825 | AJ6: =AI6+2 -> 45827 | AK6: =AI6+3 -> 45828 | AL6: PROY-1 | AM6: PROY-2 | AN6: PROY-3 | AO6: ASIST | AP6: PROM | AR6: =AI6+7 -> 45832 | AS6: =AR6+2 -> 45834 | AT6: =AR6+3 -> 45835 | AU6: EXAMEN | AV6: PROY-1 | AW6: PROY¿2 | AX6: ASIST | AY6: PROM | BA6: =AR6+7 -> 45839 | BB6: =BA6+2 -> 45841 | BC6: =BB6+1 -> 45842 | BD6: PRAC | BE6: EXAMEN | BF6: PROY-1 | BG6: PROY-2 | BH6: ASIST | BI6: PROM | BJ6: PRAC04 | BK6: =BA6+7 -> 45846 | BL6: =BK6+2 -> 45848 | BM6: =BL6+1 -> 45849 | BN6: PROY-01 | BO6: PROY-02 | BP6: EXAMEN | BQ6: ASIST | BR6: PROM | BY6: =BK6+7 -> 45853 | BZ6: =BY6+2 -> 45855 | CA6: =BY6+3 -> 45856 | CB6: PROY-01 | CC6: PROY-02 | CD6: PROY-03 | CE6: CYE | CF6: EXAMEN | CG6: CAR TRAB | CH6: ASIST | CI6: PROM | CK6: =BY6+7 -> 45860 | CL6: =CK6+2 -> 45862 | CM6: =CL6+1 -> 45863 | CN6: CARP TRAB | CO6: FOLDER | CP6: EXAMEN | CQ6: PROY-INDV | CR6: ASIST | CS6: PROM | CY6: =CK6+7 -> 45867 | CZ6: =CY6+2 -> 45869 | DA6: =CZ6+1 -> 45870 | DC6: ASIST | DD6: PROM | DF6: EXAMEN | DG6: EXAMEN
A7: 1 | B7: ='RELACION ESTUDIANTES - 2022'!C6 -> CALDERON FALCON DORIAM JOSUE | D7: AD | E7: A | F7: A | H7: =P7 -> AD | I7: A | K7: AD | L7: B | M7: A | P7: =AA7 -> AD | Q7: A | S7: AD | T7: AD | U7: B | AA7: =AO7 -> AD | AB7: A | AI7: AD | AJ7: AD | AK7: AD | AO7: =AX7 -> AD | AP7: AD | AR7: AD | AS7: A | AT7: A | AU7: A | AX7: =BH7 -> AD | AY7: A | BA7: B | BB7: AD | BC7: A | BE7: A | BH7: =BQ7 -> AD | BI7: A | BK7: AD | BL7: AD | BM7: AD | BP7: A | BQ7: =CH7 -> AD | BR7: AD | BY7: AD | BZ7: A | CA7: AD | CF7: A | CH7: =CR7 -> AD | CI7: AD | CK7: AD | CP7: A | CR7: =DE7 -> AD | CS7: AD | DE7: AD | DF7: B | DG7: AD | DH7: A
A8: 2 | B8: ='RELACION ESTUDIANTES - 2022'!C7 -> CAMPOS PALOMINO MAXIMO NASSIR | D8: C | E8: A | F8: B | H8: =P8 -> B | I8: B | K8: C | L8: C | M8: A | P8: =AA8 -> B | Q8: B | S8: A | T8: A | U8: B | AA8: =AO8 -> B | AB8: A | AI8: B | AJ8: A | AK8: C | AO8: =AX8 -> B | AP8: B | AR8: A | AS8: C | AT8: B | AU8: B | AX8: =BH8 -> B | AY8: B | BA8: C | BB8: C | BC8: C | BE8: B | BH8: =BQ8 -> B | BI8: C | BK8: AD | BL8: C | BM8: A | BP8: B | BQ8: =CH8 -> B | BR8: B | BY8: AD | BZ8: A | CF8: B | CH8: =CR8 -> B | CI8: A | CK8: B | CP8: B | CR8: =DE8 -> B | CS8: B | DE8: B | DF8: C | DG8: AD | DH8: B
A9: 3 | B9: ='RELACION ESTUDIANTES - 2022'!C8 -> CHUQUIZUTA VALENCIA FRANKLIN YAZID | D9: C | E9: A | F9: B | H9: =P9 -> B | I9: B | K9: AD | L9: AD | M9: C | P9: =AA9 -> B | Q9: B | S9: AD | T9: A | U9: B | AA9: =AO9 -> B | AB9: A | AI9: C | AJ9: C | AK9: C | AO9: =AX9 -> B | AP9: C | AR9: C | AS9: A | AT9: B | AU9: B | AX9: =BH9 -> B | AY9: B | BA9: C | BB9: A | BC9: C | BE9: B | BH9: =BQ9 -> B | BI9: C | BK9: C | BL9: C | BM9: A | BP9: B | BQ9: =CH9 -> B | BR9: B | BY9: B | BZ9: A | CF9: B | CH9: =CR9 -> B | CI9: B | CK9: C | CP9: B | CR9: =DE9 -> B | CS9: B | DE9: B | DF9: C | DG9: AD | DH9: B
A10: 4 | B10: ='RELACION ESTUDIANTES - 2022'!C9 -> COTAQUISPE GALVEZ YOJAN ANDRES | D10: B | E10: B | F10: B | H10: =P10 -> A | I10: B | K10: B | L10: C | M10: B | P10: =AA10 -> A | Q10: B | S10: A | T10: B | U10: B | AA10: =AO10 -> A | AB10: A | AI10: B | AJ10: B | AK10: B | AO10: =AX10 -> A | AP10: B | AR10: A | AS10: A | AT10: A | AU10: B | AX10: =BH10 -> A | AY10: A | BA10: B | BB10: A | BC10: A | BE10: B | BH10: =BQ10 -> A | BI10: A | BK10: A | BL10: A | BM10: B | BP10: B | BQ10: =CH10 -> A | BR10: A | BY10: C | BZ10: B | CA10: AD | CF10: B | CH10: =CR10 -> A | CI10: B | CK10: C | CP10: B | CR10: =DE10 -> A | CS10: B | DE10: A | DF10: C | DG10: AD | DH10: B
A11: 5 | B11: ='RELACION ESTUDIANTES - 2022'!C10 -> HUAMANI PAUCAR LUIS ALFREDO | D11: B | E11: A | F11: AD | H11: =P11 -> AD | I11: A | K11: A | L11: AD | M11: A | P11: =AA11 -> AD | Q11: A | S11: AD | T11: AD | U11: A | AA11: =AO11 -> AD | AB11: AD | AI11: C | AJ11: A | AK11: AD | AO11: =AX11 -> AD | AP11: B | AR11: A | AS11: A | AT11: A | AU11: AD | AX11: =BH11 -> AD | AY11: A | BA11: AD | BB11: AD | BC11: A | BE11: AD | BH11: =BQ11 -> AD | BI11: AD | BK11: AD | BL11: AD | BM11: A | BP11: AD | BQ11: =CH11 -> AD | BR11: AD | BY11: AD | BZ11: A | CF11: AD | CH11: =CR11 -> AD | CI11: A | CK11: B | CP11: AD | CR11: =DE11 -> AD | CS11: A | DE11: AD | DF11: AD | DG11: AD | DH11: AD
A12: 6 | B12: ='RELACION ESTUDIANTES - 2022'!C11 -> HUARCAYA BACAS HENRY VICENTE | D12: A | E12: A | F12: AD | H12: =P12 -> AD | I12: A | K12: AD | L12: B | M12: A | P12: =AA12 -> AD | Q12: A | S12: AD | T12: AD | U12: B | AA12: =AO12 -> AD | AB12: A | AI12: AD | AJ12: AD | AK12: AD | AO12: =AX12 -> AD | AP12: AD | AR12: A | AS12: A | AT12: A | AU12: A | AX12: =BH12 -> AD | AY12: A | BA12: AD | BB12: AD | BC12: A | BE12: A | BH12: =BQ12 -> AD | BI12: AD | BK12: AD | BL12: A | BM12: AD | BP12: A | BQ12: =CH12 -> AD | BR12: AD | BY12: AD | BZ12: A | CF12: A | CH12: =CR12 -> AD | CI12: A | CK12: AD | CP12: A | CR12: =DE12 -> AD | CS12: AD | DE12: AD | DF12: B | DG12: AD | DH12: A
A13: 7 | B13: ='RELACION ESTUDIANTES - 2022'!C12 -> HUAYHUAMEZA LEÑAN DEYVIS | D13: B | E13: A | F13: AD | H13: =P13 -> AD | I13: A | K13: B | L13: B | M13: B | P13: =AA13 -> AD | Q13: B | S13: A | T13: A | U13: B | AA13: =AO13 -> AD | AB13: A | AI13: A | AJ13: A | AK13: C | AO13: =AX13 -> AD | AP13: B | AR13: A | AS13: A | AT13: A | AU13: B | AX13: =BH13 -> AD | AY13: A | BA13: B | BB13: A | BC13: A | BE13: B | BH13: =BQ13 -> AD | BI13: A | BK13: A | BL13: A | BM13: A | BP13: B | BQ13: =CH13 -> AD | BR13: A | BY13: A | BZ13: A | CF13: B | CH13: =CR13 -> AD | CI13: A | CK13: B | CP13: B | CR13: =DE13 -> AD | CS13: B | DE13: AD | DF13: C | DG13: B | DH13: B
A14: 9 | B14: ='RELACION ESTUDIANTES - 2022'!C13 -> JUSCAMAYTA HUARACC YOSSIMAR BAYRON | D14: A | E14: A | F14: AD | H14: =P14 -> AD | I14: A | K14: AD | L14: AD | M14: B | P14: =AA14 -> AD | Q14: A | S14: AD | T14: AD | U14: B | AA14: =AO14 -> AD | AB14: A | AI14: A | AJ14: A | AK14: AD | AO14: =AX14 -> AD | AP14: AD | AR14: A | AS14: A | AT14: A | AU14: B | AX14: =BH14 -> AD | AY14: A | BA14: AD | BB14: A | BC14: C | BE14: B | BH14: =BQ14 -> AD | BI14: B | BK14: A | BL14: A | BM14: AD | BP14: B | BQ14: =CH14 -> AD | BR14: A | BY14: AD | BZ14: A | CF14: B | CH14: =CR14 -> AD | CI14: A | CK14: AD | CP14: B | CR14: =DE14 -> AD | CS14: A | DE14: AD | DF14: C | DG14: AD | DH14: B
A15: 10 | B15: ='RELACION ESTUDIANTES - 2022'!C14 -> LEVANO GALINDO CRISTOPHER ANDRES | D15: A | E15: A | F15: B | H15: =P15 -> AD | I15: A | K15: AD | L15: B | M15: A | P15: =AA15 -> AD | Q15: A | S15: AD | T15: AD | U15: B | AA15: =AO15 -> AD | AB15: A | AI15: A | AJ15: A | AK15: B | AO15: =AX15 -> AD | AP15: A | AR15: AD | AS15: A | AT15: A | AU15: B | AX15: =BH15 -> AD | AY15: A | BA15: A | BB15: AD | BC15: A | BE15: B | BH15: =BQ15 -> AD | BI15: A | BK15: AD | BL15: A | BM15: A | BP15: B | BQ15: =CH15 -> AD | BR15: A | BY15: AD | BZ15: A | CA15: AD | CF15: B | CH15: =CR15 -> AD | CI15: A | CK15: AD | CP15: B | CR15: =DE15 -> AD | CS15: A | DE15: AD | DF15: C | DG15: AD | DH15: B
A16: 11 | B16: ='RELACION ESTUDIANTES - 2022'!C15 -> LINARES ZAPATA CARLOS ALBERTO | D16: B | E16: C | F16: B | H16: =P16 -> B | I16: B | K16: C | L16: C | M16: C | P16: =AA16 -> B | Q16: C | S16: A | T16: A | U16: B | AA16: =AO16 -> B | AB16: A | AI16: A | AJ16: C | AK16: C | AO16: =AX16 -> B | AP16: B | AR16: AD | AS16: A | AT16: A | AU16: B | AX16: =BH16 -> B | AY16: A | BA16: B | BB16: AD | BC16: C | BE16: B | BH16: =BQ16 -> B | BI16: B | BK16: AD | BL16: A | BM16: A | BP16: B | BQ16: =CH16 -> B | BR16: A | BY16: AD | BZ16: A | CA16: AD | CF16: B | CH16: =CR16 -> B | CI16: A | CK16: B | CP16: B | CR16: =DE16 -> B | CS16: B | DE16: B | DF16: C | DG16: AD | DH16: B
A17: 12 | B17: ='RELACION ESTUDIANTES - 2022'!C16 -> MOZO HUAYRA PEDRO CALEB | D17: B | E17: B | F17: B | H17: =P17 -> AD | I17: B | K17: B | L17: B | M17: C | P17: =AA17 -> AD | Q17: B | S17: B | T17: A | U17: B | AA17: =AO17 -> AD | AB17: A | AI17: B | AJ17: A | AK17: C | AO17: =AX17 -> AD | AP17: B | AR17: A | AS17: A | AT17: A | AU17: B | AX17: =BH17 -> AD | AY17: A | BA17: B | BB17: A | BC17: A | BE17: B | BH17: =BQ17 -> AD | BI17: A | BK17: A | BL17: A | BM17: A | BP17: B | BQ17: =CH17 -> AD | BR17: A | BY17: A | BZ17: A | CF17: B | CH17: =CR17 -> AD | CI17: A | CK17: B | CP17: B | CR17: =DE17 -> AD | CS17: B | DE17: AD | DF17: C | DG17: B | DH17: B
A18: 13 | B18: ='RELACION ESTUDIANTES - 2022'!C17 -> NECOCHEA CASTILLO ANTHONY ORLANDO | D18: B | E18: A | F18: B | H18: =P18 -> A | I18: A | K18: AD | L18: AD | M18: C | P18: =AA18 -> A | Q18: B | S18: AD | T18: AD | U18: B | AA18: =AO18 -> A | AB18: A | AI18: B | AJ18: A | AK18: A | AO18: =AX18 -> A | AP18: A | AR18: A | AS18: A | AT18: A | AU18: B | AX18: =BH18 -> A | AY18: A | BA18: C | BB18: A | BC18: A | BE18: B | BH18: =BQ18 -> A | BI18: B | BK18: A | BL18: A | BM18: A | BP18: B | BQ18: =CH18 -> A | BR18: A | BY18: AD | BZ18: B | CF18: B | CH18: =CR18 -> A | CI18: A | CK18: B | CP18: B | CR18: =DE18 -> A | CS18: B | DE18: A | DF18: C | DG18: AD | DH18: B
A19: 14 | B19: ='RELACION ESTUDIANTES - 2022'!C18 -> ÑAÑEZ CARRASQUEL DIEGO ALEJANDRO | D19: A | E19: A | F19: AD | H19: =P19 -> B | I19: A | K19: AD | L19: B | M19: A | P19: =AA19 -> B | Q19: A | S19: C | T19: AD | U19: A | AA19: =AO19 -> B | AB19: B | AI19: A | AJ19: A | AK19: AD | AO19: =AX19 -> B | AP19: A | AR19: A | AS19: AD | AT19: A | AU19: C | AX19: =BH19 -> B | AY19: B | BA19: B | BB19: AD | BC19: C | BE19: C | BH19: =BQ19 -> B | BI19: B | BK19: C | BL19: C | BM19: C | BP19: C | BQ19: =CH19 -> B | BR19: C | BY19: C | BZ19: C | CF19: C | CH19: =CR19 -> B | CI19: C | CK19: C | CP19: C | CR19: =DE19 -> B | CS19: C | DE19: B | DF19: C | DG19: C | DH19: C
A20: 15 | B20: ='RELACION ESTUDIANTES - 2022'!C19 -> PEREZ MUÑOZ SAMIER ALEJANDRO | D20: A | E20: A | F20: B | H20: =P20 -> A | I20: A | K20: AD | L20: AD | M20: AD | P20: =AA20 -> A | Q20: AD | S20: AD | T20: AD | U20: B | AA20: =AO20 -> A | AB20: A | AI20: AD | AJ20: C | AK20: C | AO20: =AX20 -> A | AP20: B | AR20: A | AS20: A | AT20: A | AU20: A | AX20: =BH20 -> A | AY20: A | BA20: A | BB20: AD | BC20: A | BE20: A | BH20: =BQ20 -> A | BI20: A | BK20: A | BL20: A | BM20: AD | BP20: A | BQ20: =CH20 -> A | BR20: A | BY20: AD | BZ20: A | CF20: A | CH20: =CR20 -> A | CI20: A | CK20: AD | CP20: A | CR20: =DE20 -> A | CS20: A | DE20: A | DF20: B | DG20: AD | DH20: A
A21: 16 | B21: ='RELACION ESTUDIANTES - 2022'!C20 -> PICHARDE AQUINO CARLOS GABRIEL | D21: A | E21: C | F21: AD | H21: =P21 -> A | I21: B | K21: AD | L21: AD | M21: AD | P21: =AA21 -> A | Q21: AD | S21: A | T21: AD | U21: B | AA21: =AO21 -> A | AB21: A | AI21: AD | AJ21: A | AK21: C | AO21: =AX21 -> A | AP21: B | AR21: A | AS21: A | AT21: A | AU21: A | AX21: =BH21 -> A | AY21: A | BA21: A | BB21: AD | BC21: C | BE21: A | BH21: =BQ21 -> A | BI21: B | BK21: AD | BL21: A | BM21: AD | BP21: A | BQ21: =CH21 -> A | BR21: A | BY21: AD | BZ21: A | CF21: A | CH21: =CR21 -> A | CI21: A | CK21: AD | CP21: A | CR21: =DE21 -> A | CS21: A | DE21: A | DF21: B | DG21: AD | DH21: A
A22: 18 | B22: ='RELACION ESTUDIANTES - 2022'!C21 -> VEGA CANALES ALVEYRO CRISTOBAL | D22: B | E22: C | F22: B | H22: =P22 -> C | I22: B | K22: C | L22: B | M22: C | P22: =AA22 -> C | Q22: B | S22: C | T22: C | U22: C | AA22: =AO22 -> C | AB22: C | AI22: C | AJ22: C | AK22: C | AO22: =AX22 -> C | AP22: C | AR22: C | AS22: C | AT22: C | AU22: C | AX22: =BH22 -> C | AY22: C | BA22: C | BB22: C | BC22: A | BE22: C | BH22: =BQ22 -> C | BI22: C | BK22: C | BL22: C | BM22: C | BP22: C | BQ22: =CH22 -> C | BR22: C | BY22: C | BZ22: C | CF22: C | CH22: =CR22 -> C | CI22: C | CK22: C | CP22: C | CR22: =DE22 -> C | CS22: C | DE22: C | DF22: C | DG22: C | DH22: C
A23: 19 | B23: ='RELACION ESTUDIANTES - 2022'!C22 -> 0 | H23: =P23 -> 0 | P23: =AA23 -> 0 | AA23: =AO23 -> 0 | AO23: =AX23 -> 0 | AX23: =BH23 -> 0 | BH23: =BQ23 -> 0 | CH23: =CR23 -> 0 | CR23: =DE23 -> 0 | DF23: =COUNTIF(AC23:DB23,"OK") -> 0 | DG23: =DF23*2+4 -> 4
A24: 20 | B24: ='RELACION ESTUDIANTES - 2022'!C23 -> 0 | H24: =P24 -> 0 | P24: =AA24 -> 0 | AA24: =AO24 -> 0 | AO24: =AX24 -> 0 | AX24: =BH24 -> 0 | BE24: X5 | BH24: =BQ24 -> 0 | CA24: DIA | CF24: DIA | CH24: =CR24 -> 0 | CR24: =DE24 -> 0 | DF24: =COUNTIF(AC24:DB24,"OK") -> 0 | DG24: =DF24*2+4 -> 4
A25: 21 | BX25: =IF(BY25>=18,"AD",IF(BY25>=15,"A",IF(BY25>=11,"B"," "))) | CA25: DEL | CF25: DEL | CJ25: =IF(CM25>=18,"AD",IF(CM25>=15,"A",IF(CM25>=11,"B"," "))) | DF25: =COUNTIF(AC25:DB25,"OK") -> 0 | DG25: =DF25*2+4 -> 4
A26: 22 | Q26: =ROUND(AVERAGE(O26:P26),0) -> #DIV/0! | AQ26: =IF(AR26>=18,"AD",IF(AR26>=15,"A",IF(AR26>=11,"B"," "))) | BJ26: =IF(BK26>=18,"AD",IF(BK26>=15,"A",IF(BK26>=11,"B"," "))) | BX26: =IF(BY26>=18,"AD",IF(BY26>=15,"A",IF(BY26>=11,"B"," "))) | CA26: LOGRO | CF26: LOGRO | CJ26: =IF(CM26>=18,"AD",IF(CM26>=15,"A",IF(CM26>=11,"B"," "))) | DF26: =COUNTIF(AC26:DB26,"OK") -> 0 | DG26: =DF26*2+4 -> 4
A27: 23 | Q27: =ROUND(AVERAGE(O27:P27),0) -> #DIV/0! | AB27: =ROUND(AVERAGE(X27:AA27),0) -> #DIV/0! | AP27: =ROUND(AVERAGE(AI27:AO27),0) -> #DIV/0! | AQ27: =IF(AR27>=18,"AD",IF(AR27>=15,"A",IF(AR27>=11,"B"," "))) | AY27: =ROUND(AVERAGE(AR27:AX27),0) -> #DIV/0! | AZ27: =IF(BA27>=18,"AD",IF(BA27>=15,"A",IF(BA27>=11,"B"," "))) | BI27: =ROUND(AVERAGE(BA27:BH27),0) -> #DIV/0! | BJ27: =IF(BK27>=18,"AD",IF(BK27>=15,"A",IF(BK27>=11,"B"," "))) | BX27: =IF(BY27>=18,"AD",IF(BY27>=15,"A",IF(BY27>=11,"B"," "))) | CA27: X5 | CI27: =ROUND(AVERAGE(BY27:CH27),0) -> #DIV/0! | CJ27: =IF(CM27>=18,"AD",IF(CM27>=15,"A",IF(CM27>=11,"B"," "))) | CS27: =ROUND(AVERAGE(CM27:CR27),0) -> #DIV/0! | DF27: =COUNTIF(AC27:DB27,"OK") -> 0 | DG27: =DF27*2+4 -> 4
A28: 24 | I28: =ROUND(AVERAGE(D28:H28),0) -> #DIV/0! | Q28: =ROUND(AVERAGE(O28:P28),0) -> #DIV/0! | AB28: =ROUND(AVERAGE(X28:AA28),0) -> #DIV/0! | AP28: =ROUND(AVERAGE(AI28:AO28),0) -> #DIV/0! | AQ28: =IF(AR28>=18,"AD",IF(AR28>=15,"A",IF(AR28>=11,"B"," "))) | AY28: =ROUND(AVERAGE(AR28:AX28),0) -> #DIV/0! | AZ28: =IF(BA28>=18,"AD",IF(BA28>=15,"A",IF(BA28>=11,"B"," "))) | BI28: =ROUND(AVERAGE(BA28:BH28),0) -> #DIV/0! | BJ28: =IF(BK28>=18,"AD",IF(BK28>=15,"A",IF(BK28>=11,"B"," "))) | BR28: =ROUND(AVERAGE(BK28:BQ28),0) -> #DIV/0! | BX28: =IF(BY28>=18,"AD",IF(BY28>=15,"A",IF(BY28>=11,"B"," "))) | CI28: =ROUND(AVERAGE(BY28:CH28),0) -> #DIV/0! | CJ28: =IF(CM28>=18,"AD",IF(CM28>=15,"A",IF(CM28>=11,"B"," "))) | CS28: =ROUND(AVERAGE(CM28:CR28),0) -> #DIV/0! | DF28: =COUNTIF(AC28:DB28,"OK") -> 0 | DG28: =DF28*2+4 -> 4
