Workbook

Sheet RELACION GENERAL
B2: PROF. SE COMPARTE CON - CONSTRUCCION CIVIL | C2: PROF. SE COMPARTE CON - MECANICA DE PROD. | D2: PROF. SE COMPARTE CON - COMPUTACION
B5: 3ro "D" | C5: 5to "I" | D5: 5to "R"
A6: 1 | B6: CASAVILCA ACOSTA YZUHAIM HUGO ALBERTO | C6: CALDERON FALCON DORIAM JOSUE | D6: APUMAITA GUTIERREZ JULIO LUCIANO
A7: 2 | B7: CASTRO VARGAS JHORDAN ANDREE WILLIAN | C7: CAMPOS PALOMINO MAXIMO NASSIR | D7: CABRERA ORTIZ THIAGO ARMANDO
A8: 3 | B8: CONDE GAMBOA JHONATAN RODRIGO | C8: CHUQUIZUTA VALENCIA FRANKLIN YAZID | D8: CACERES CAHUANA JESUS ANDRES
A9: 4 | B9: CUADROS ZEVALLOS ANGELO DAVID | C9: COTAQUISPE GALVEZ YOJAN ANDRES | D9: DE LA CRUZ SIGUAS LUIS ALBERTO
A10: 5 | B10: GALINDO HERNANDEZ EMERSON FELIPE | C10: HUAMANI PAUCAR LUIS ALFREDO | D10: HERNANDEZ PEÑA JOSEPH ANDREE
A11: 6 | B11: HERNANDEZ ENRIQUEZ JARED MIGUEL | C11: HUARCAYA BACAS HENRY VICENTE | D11: JUAREZ LEGUA VICTOR DANIEL
A12: 7 | B12: HERNANDEZ MUNIVE NICOLAS ERNESTO | C12: HUAYHUAMEZA LEÑAN DEYVIS | D12: MEJIA SIMON VICENTE MISAEL
A13: 8 | B13: NAVAS GOMEZ BENJAMIN HUMBERTO | C13: JUSCAMAYTA HUARACC YOSSIMAR BAYRON | D13: MEZA CARDENAS FERNANDO ALEXANDER
A14: 9 | B14: PACHECO ESPILLCO MATIAS DEYAIR | C14: LEVANO GALINDO CRISTOPHER ANDRES | D14: MISAICO CHAHUAILA JUAN DAVID
A15: 10 | B15: RAMIREZ ESCRIBA JHERCY HUSCIEL | C15: LINARES ZAPATA CARLOS ALBERTO | D15: MUÑOZ QUINTANILLA JACKXEL EDUARDO
A16: 11 | B16: SANCHEZ SANTIAGO KALEB MOISES | C16: MOZO HUAYRA PEDRO CALEB | D16: PEÑA ASCENCIO CESAR LUIS
A17: 12 | B17: SEGOVIA LICAS DANGELO KENDALL | C17: NECOCHEA CASTILLO ANTHONY ORLANDO | D17: SOSA FUENTES UBALDO FRANCISCO
A18: 13 | B18: VELARDE GONZALEZ MARCOS MIGUEL | C18: ÑAÑEZ CARRASQUEL DIEGO ALEJANDRO
A19: 14 | B19: YARCURI CRISOSTOMO JUAN DIEGO | C19: PEREZ MUÑOZ SAMIER ALEJANDRO
A20: 15 | C20: PICHARDE AQUINO CARLOS GABRIEL
A21: 16 | C21: VEGA CANALES ALVEYRO CRISTOBAL
A22: 17
A23: 18
A24: 19
A25: 20
A26: 21
A27: 22
A28: 23
A29: 24
A30: 25
A31: 26
A32: 27
A33: 28
... A42: 37

Sheet 3D-B-1-ASIST
A1: REGISTRO AUXILIAR DE EDUCACIÓN PARA EL TRABAJO - ELECTRICIDAD - 2021 -- 1º BIMESTRE
A2: Nº DE ORDEN | D2: I. E. | Z2: Promedio de Capacidades y Actitudes | AF2: Promedio de Capacidades y Actitudes
D3: "SAN LUIS GONZAGA" | H3: APLICA HABILIDADES Y TECNICAS | L3: TRABAJA COOPERATIVAMENTE PARA LOGRAR OBJETIVOS Y METAS | P3: EVALUA LOS RESULTADOS DEL PROYECTO | T3: SE DESEMVUELVE EN ENTORNOS VIRTUALES GENERDAS POR LAS TIC | W3: GESTIONA SU APRENDIZAJE DE MAERA AUTONOMA | Z3: PC-1 | AA3: PC-2 | AB3: PC-3 | AC3: PC-4 | AD3: PC-4 | AE3: PC-4 | AF3: PC-1 | AG3: PC-2 | AH3: PC-3
B4: ESPECIALIDAD: ELECTRICIDAD | E4: Evaluación Diagnostica: Desarrolla la gestion de propuesta de valor con ideas creativa y puntos de vista reveladores | G4: PROMEDIO C-1 | H4: Gestiona emprendimientos economicos o sociales de su interes proponiendo un reto o desafio y realizando la empatia para recoger datos | I4: reconoce y valora la seguridad electrica en su lugar de trabajo o estudio | J4: Promueve y ejecuta actividades de prevensión frente a un riesgo electrico | K4: PROMEDIO C-2 | L4: Trabaja cooperativamente recombinado sus roles y responsabilidades individuales para el logro de la competencia | M4: Organiza su area de trabajo para su adecuado trabajo remoto y uso de TIC | O4: PROMEDIO C-3 | P4: Implementa tecnicas (malla receptora) optimamente para evaluar su proptotipo y proyecto de meprendimiento | Q4: Incorpora mejoras innovadoras y creativas en el proyecto basico de emprendimiento orientado a la especialidad de EPT. | S4: PROMEDIO C-4 | T4: Se desenvuelve en los entornos virtuales cuando integra distintas actividades, actitudes y conocimientos de diversos contextos | W4: Gestiona su aprendizaje de manera autónoma al darse cuenta lo que debe aprender al distinguir lo sencillo o complejo de una tarea, y por ende define metas personales respaldándose en sus potencialidades
B5: GRADO Y SECCIÓN: 5 "J"
B6: BIMESTRE: I
B7: PROFESOR (A): Julio César
B8: SORIA QUISPE
B9: APELLIDOS Y NOMBRES
A11: 01 | E11: 16 | G11: =ROUND(AVERAGE(E11:F11),0) -> 16 | K11: =ROUND(AVERAGE(H11:J11),0) -> #DIV/0! | O11: =ROUND(AVERAGE(L11:N11),) -> #DIV/0! | Z11: =G11 -> 16 | AA11: =K11 -> #DIV/0! | AB11: =O11 -> #DIV/0! | AE11: =#REF! -> #REF! | AF11: =M11 -> 0 | AG11: =Q11 -> 0 | AH11: =U11 -> 0
A12: 02 | G12: =ROUND(AVERAGE(E12:F12),0) -> #DIV/0! | K12: =ROUND(AVERAGE(H12:J12),0) -> #DIV/0! | O12: =ROUND(AVERAGE(L12:N12),) -> #DIV/0! | Z12: =G12 -> #DIV/0! | AA12: =K12 -> #DIV/0! | AB12: =O12 -> #DIV/0! | AE12: =#REF! -> #REF! | AF12: =M12 -> 0 | AG12: =Q12 -> 0 | AH12: =U12 -> 0
A13: 03 | G13: =ROUND(AVERAGE(E13:F13),0) -> #DIV/0! | K13: =ROUND(AVERAGE(H13:J13),0) -> #DIV/0! | O13: =ROUND(AVERAGE(L13:N13),) -> #DIV/0! | Z13: =G13 -> #DIV/0! | AA13: =K13 -> #DIV/0! | AB13: =O13 -> #DIV/0! | AE13: =#REF! -> #REF! | AF13: =M13 -> 0 | AG13: =Q13 -> 0 | AH13: =U13 -> 0
A14: 04 | G14: =ROUND(AVERAGE(E14:F14),0) -> #DIV/0! | K14: =ROUND(AVERAGE(H14:J14),0) -> #DIV/0! | O14: =ROUND(AVERAGE(L14:N14),) -> #DIV/0! | Z14: =G14 -> #DIV/0! | AA14: =K14 -> #DIV/0! | AB14: =O14 -> #DIV/0! | AE14: =#REF! -> #REF! | AF14: =M14 -> 0 | AG14: =Q14 -> 0 | AH14: =U14 -> 0
A15: 05 | G15: =ROUND(AVERAGE(E15:F15),0) -> #DIV/0! | K15: =ROUND(AVERAGE(H15:J15),0) -> #DIV/0! | O15: =ROUND(AVERAGE(L15:N15),) -> #DIV/0! | Z15: =G15 -> #DIV/0! | AA15: =K15 -> #DIV/0! | AB15: =O15 -> #DIV/0! | AE15: =#REF! -> #REF! | AF15: =M15 -> 0 | AG15: =Q15 -> 0 | AH15: =U15 -> 0
A16: 06 | G16: =ROUND(AVERAGE(E16:F16),0) -> #DIV/0! | K16: =ROUND(AVERAGE(H16:J16),0) -> #DIV/0! | O16: =ROUND(AVERAGE(L16:N16),) -> #DIV/0! | Z16: =G16 -> #DIV/0! | AA16: =K16 -> #DIV/0! | AB16: =O16 -> #DIV/0! | AE16: =#REF! -> #REF! | AF16: =M16 -> 0 | AG16: =Q16 -> 0 | AH16: =U16 -> 0
A17: 07 | G17: =ROUND(AVERAGE(E17:F17),0) -> #DIV/0! | K17: =ROUND(AVERAGE(H17:J17),0) -> #DIV/0! | O17: =ROUND(AVERAGE(L17:N17),) -> #DIV/0! | Z17: =G17 -> #DIV/0! | AA17: =K17 -> #DIV/0! | AB17: =O17 -> #DIV/0! | AE17: =#REF! -> #REF! | AF17: =M17 -> 0 | AG17: =Q17 -> 0 | AH17: =U17 -> 0
A18: 08 | G18: =ROUND(AVERAGE(E18:F18),0) -> #DIV/0! | K18: =ROUND(AVERAGE(H18:J18),0) -> #DIV/0! | O18: =ROUND(AVERAGE(L18:N18),) -> #DIV/0! | Z18: =G18 -> #DIV/0! | AA18: =K18 -> #DIV/0! | AB18: =O18 -> #DIV/0! | AE18: =#REF! -> #REF! | AF18: =M18 -> 0 | AG18: =Q18 -> 0 | AH18: =U18 -> 0
A19: 09 | G19: =ROUND(AVERAGE(E19:F19),0) -> #DIV/0! | K19: =ROUND(AVERAGE(H19:J19),0) -> #DIV/0! | O19: =ROUND(AVERAGE(L19:N19),) -> #DIV/0! | Z19: =G19 -> #DIV/0! | AA19: =K19 -> #DIV/0! | AB19: =O19 -> #DIV/0! | AE19: =#REF! -> #REF! | AF19: =M19 -> 0 | AG19: =Q19 -> 0 | AH19: =U19 -> 0
A20: 10 | G20: =ROUND(AVERAGE(E20:F20),0) -> #DIV/0! | K20: =ROUND(AVERAGE(H20:J20),0) -> #DIV/0! | O20: =ROUND(AVERAGE(L20:N20),) -> #DIV/0! | Z20: =G20 -> #DIV/0! | AA20: =K20 -> #DIV/0! | AB20: =O20 -> #DIV/0! | AE20: =#REF! -> #REF! | AF20: =M20 -> 0 | AG20: =Q20 -> 0 | AH20: =U20 -> 0
A21: 11 | G21: =ROUND(AVERAGE(E21:F21),0) -> #DIV/0! | K21: =ROUND(AVERAGE(H21:J21),0) -> #DIV/0! | O21: =ROUND(AVERAGE(L21:N21),) -> #DIV/0! | Z21: =G21 -> #DIV/0! | AA21: =K21 -> #DIV/0! | AB21: =O21 -> #DIV/0! | AE21: =#REF! -> #REF! | AF21: =M21 -> 0 | AG21: =Q21 -> 0 | AH21: =U21 -> 0
A22: 12 | G22: =ROUND(AVERAGE(E22:F22),0) -> #DIV/0! | K22: =ROUND(AVERAGE(H22:J22),0) -> #DIV/0! | O22: =ROUND(AVERAGE(L22:N22),) -> #DIV/0! | Z22: =G22 -> #DIV/0! | AA22: =K22 -> #DIV/0! | AB22: =O22 -> #DIV/0! | AE22: =#REF! -> #REF! | AF22: =M22 -> 0 | AG22: =Q22 -> 0 | AH22: =U22 -> 0
A23: 13 | G23: =ROUND(AVERAGE(E23:F23),0) -> #DIV/0! | K23: =ROUND(AVERAGE(H23:J23),0) -> #DIV/0! | O23: =ROUND(AVERAGE(L23:N23),) -> #DIV/0! | Z23: =G23 -> #DIV/0! | AA23: =K23 -> #DIV/0! | AB23: =O23 -> #DIV/0! | AE23: =#REF! -> #REF! | AF23: =M23 -> 0 | AG23: =Q23 -> 0 | AH23: =U23 -> 0
... A43: 33 | G43: =ROUND(AVERAGE(E43:F43),0) -> #DIV/0! | K43: =ROUND(AVERAGE(H43:J43),0) -> #DIV/0! | O43: =ROUND(AVERAGE(L43:N43),) -> #DIV/0! | Z43: =G43 -> #DIV/0! | AA43: =K43 -> #DIV/0! | AB43: =O43 -> #DIV/0! | AE43: =#REF! -> #REF! | AF43: =M43 -> 0 | AG43: =Q43 -> 0 | AH43: =U43 -> 0
D49: REGISTRO DE ASISTENCIA DEL 3RO-D -- 2DO BIM
B50: TERCERO "D"
E52: SEMANA 11 | H52: SEMANA 12 | K52: SEMANA 13 | N52: SEMANA 14 | Q52: SEMANA 15 | T52: SEMANA 16 | W52: SEMANA 17 | Z52: SEMANA 18 | AC52: SEMANA 19 | AF52: SEMANA 20 | AV52: SEMANA 15 | AY52: SEMANA 16
E53: LUNES | F53: MARTES | G53: MIECOLES | H53: LUNES | I53: MARTES | J53: MIECOLES | K53: LUNES | L53: MARTES | M53: MIECOLES | N53: LUNES | O53: MARTES | P53: MIECOLES | Q53: LUNES | R53: MARTES | S53: MIECOLES | T53: LUNES | U53: MARTES | V53: MIECOLES | W53: LUNES | X53: MARTES | Y53: MIECOLES | Z53: LUNES | AA53: MARTES | AB53: MIECOLES | AC53: LUNES | AD53: MARTES | AE53: MIECOLES | AF53: LUNES | AG53: MARTES | AH53: MIECOLES
A54: Nº | B54: APELLIDOS Y NOMBRES | C54: CELULARES - PP FF | D54: CELULARES | E54: 45803 | F54: =E54+1 -> 45804 | G54: =F54+1 -> 45805 | H54: =E54+7 -> 45810 | I54: =H54+1 -> 45811 | J54: =I54+1 -> 45812 | K54: =H54+7 -> 45817 | L54: =K54+1 -> 45818 | M54: =L54+1 -> 45819 | N54: =K54+7 -> 45824 | O54: =N54+1 -> 45825 | P54: =O54+1 -> 45826 | Q54: =N54+7 -> 45831 | R54: =Q54+1 -> 45832 | S54: =R54+1 -> 45833 | T54: =Q54+7 -> 45838 | U54: =T54+1 -> 45839 | V54: =U54+1 -> 45840 | W54: =T54+7 -> 45845 | X54: =W54+1 -> 45846 | Y54: =X54+1 -> 45847 | Z54: =W54+7 -> 45852 | AA54: =Z54+1 -> 45853 | AB54: =AA54+1 -> 45854 | AC54: =Z54+7 -> 45859 | AD54: =AC54+1 -> 45860 | AE54: =AD54+1 -> 45861 | AF54: =AC54+7 -> 45866 | AG54: =AF54+1 -> 45867 | AH54: =AG54+1 -> 45868
A55: ='[1]final 5-J'!A11 -> 01 | B55: ='RELACION GENERAL'!B6 -> CASAVILCA ACOSTA YZUHAIM HUGO ALBERTO | E55: OK | F55: OK | G55: OK | H55: OK | I55: OK | J55: OK | K55: OK | L55: OK | M55: OK | N55: OK | O55: OK | P55: OK | Q55: DIA | R55: OK | S55: OK | T55: Ok | U55: ok | V55: ok | W55: OK | X55: OK | Y55: OK | Z55: OK | AA55: OK | AB55: OK | AC55: OK | AD55: OK | AE55: FERIADO | AI55: 2 | AJ55: 0.74 | AK55: =COUNTIF(E55:AE55,"ok")+AI55 -> 27 | AM55: =AJ55*AK55 -> 19.98 | AO55: AD
A56: ='[1]final 5-J'!A12 -> 02 | B56: ='RELACION GENERAL'!B7 -> CASTRO VARGAS JHORDAN ANDREE WILLIAN | E56: OK | F56: OK | G56: OK | H56: OK | I56: OK | J56: OK | K56: OK | L56: OK | M56: OK | N56: OK | O56: OK | P56: OK | Q56: NO | R56: OK | S56: OK | T56: Ok | U56: ok | V56: ok | W56: OK | X56: OK | Y56: OK | Z56: OK | AA56: OK | AB56: OK | AC56: OK | AD56: OK | AE56: DIA | AI56: 2 | AJ56: 0.74 | AK56: =COUNTIF(E56:AE56,"ok")+AI56 -> 27 | AM56: =AJ56*AK56 -> 19.98 | AO56: AD
A57: ='[1]final 5-J'!A13 -> 03 | B57: ='RELACION GENERAL'!B8 -> CONDE GAMBOA JHONATAN RODRIGO | E57: OK | F57: OK | G57: OK | H57: OK | I57: OK | J57: OK | K57: OK | L57: OK | M57: OK | N57: OK | O57: OK | P57: OK | Q57: LABORAB. | R57: OK | S57: OK | T57: Ok | U57: ok | V57: ok | W57: OK | X57: OK | Y57: OK | Z57: OK | AA57: OK | AB57: OK | AC57: OK | AD57: OK | AE57: DE LA | AI57: 2 | AJ57: 0.74 | AK57: =COUNTIF(E57:AE57,"ok")+AI57 -> 27 | AM57: =AJ57*AK57 -> 19.98 | AO57: AD
A58: ='[1]final 5-J'!A14 -> 04 | B58: ='RELACION GENERAL'!B9 -> CUADROS ZEVALLOS ANGELO DAVID | E58: OK | F58: OK | G58: OK | H58: OK | I58: OK | J58: OK | K58: OK | L58: OK | M58: OK | N58: OK | O58: OK | P58: OK | Q58: ANIVERSARIO | R58: OK | S58: OK | T58: Ok | U58: ok | V58: ok | W58: OK | X58: OK | Y58: OK | Z58: OK | AA58: OK | AB58: OK | AC58: OK | AD58: OK | AE58: FAP | AI58: 2 | AJ58: 0.74 | AK58: =COUNTIF(E58:AE58,"ok")+AI58 -> 27 | AM58: =AJ58*AK58 -> 19.98 | AO58: AD
A59: ='[1]final 5-J'!A15 -> 05 | B59: ='RELACION GENERAL'!B10 -> GALINDO HERNANDEZ EMERSON FELIPE | E59: OK | F59: OK | G59: OK | H59: OK | I59: OK | J59: OK | K59: OK | L59: OK | M59: OK | N59: OK | O59: OK | P59: OK | R59: OK | S59: OK | T59: Ok | U59: ok | V59: ok | W59: OK | X59: OK | Y59: OK | Z59: OK | AA59: OK | AB59: OK | AC59: OK | AD59: OK | AI59: 2 | AJ59: 0.74 | AK59: =COUNTIF(E59:AE59,"ok")+AI59 -> 27 | AM59: =AJ59*AK59 -> 19.98 | AO59: AD
A60: ='[1]final 5-J'!A16 -> 06 | B60: ='RELACION GENERAL'!B11 -> HERNANDEZ ENRIQUEZ JARED MIGUEL | E60: OK | F60: OK | G60: OK | H60: OK | I60: OK | J60: OK | K60: OK | L60: OK | M60: OK | N60: OK | O60: OK | P60: OK | R60: OK | T60: Ok | U60: ok | V60: ok | W60: OK | X60: OK | Y60: OK | Z60: OK | AA60: OK | AB60: OK | AC60: OK | AD60: OK | AI60: 2 | AJ60: 0.74 | AK60: =COUNTIF(E60:AE60,"ok")+AI60 -> 26 | AM60: =AJ60*AK60 -> 19.24 | AO60: AD
A61: ='[1]final 5-J'!A17 -> 07 | B61: ='RELACION GENERAL'!B12 -> HERNANDEZ MUNIVE NICOLAS ERNESTO | E61: OK | F61: OK | G61: OK | H61: OK | I61: OK | J61: OK | K61: OK | L61: OK | M61: OK | N61: OK | O61: OK | P61: OK | R61: OK | S61: OK | T61: Ok | U61: ok | V61: ok | W61: OK | X61: OK | Y61: OK | Z61: OK | AA61: OK | AB61: OK | AC61: OK | AD61: OK | AI61: 2 | AJ61: 0.74 | AK61: =COUNTIF(E61:AE61,"ok")+AI61 -> 27 | AM61: =AJ61*AK61 -> 19.98 | AO61: AD
A62: ='[1]final 5-J'!A18 -> 08 | B62: ='RELACION GENERAL'!B13 -> NAVAS GOMEZ BENJAMIN HUMBERTO | E62: OK | F62: OK | G62: OK | H62: OK | I62: OK | J62: OK | K62: OK | L62: OK | M62: OK | N62: OK | O62: OK | P62: OK | R62: OK | S62: OK | T62: Ok | U62: ok | V62: ok | W62: OK | X62: OK | Y62: OK | Z62: OK | AA62: OK | AB62: OK | AC62: OK | AD62: OK | AI62: 2 | AJ62: 0.74 | AK62: =COUNTIF(E62:AE62,"ok")+AI62 -> 27 | AM62: =AJ62*AK62 -> 19.98 | AO62: AD
A63: ='[1]final 5-J'!A19 -> 09 | B63: ='RELACION GENERAL'!B14 -> PACHECO ESPILLCO MATIAS DEYAIR | E63: OK | F63: OK | G63: OK | H63: OK | I63: OK | J63: OK | K63: OK | L63: OK | M63: OK | N63: OK | O63: OK | P63: OK | R63: OK | S63: OK | T63: Ok | U63: ok | V63: ok | W63: OK | X63: OK | Y63: OK | Z63: OK | AA63: OK | AB63: OK | AC63: OK | AD63: OK | AI63: 2 | AJ63: 0.74 | AK63: =COUNTIF(E63:AE63,"ok")+AI63 -> 27 | AM63: =AJ63*AK63 -> 19.98 | AO63: AD
A64: ='[1]final 5-J'!A20 -> 10 | B64: ='RELACION GENERAL'!B15 -> RAMIREZ ESCRIBA JHERCY HUSCIEL | E64: OK | F64: OK | H64: OK | I64: OK | J64: OK | L64: OK | M64: OK | N64: OK | O64: OK | P64: OK | R64: OK | S64: OK | T64: Ok | U64: ok | W64: OK | X64: OK | Y64: OK | Z64: OK | AA64: OK | AB64: OK | AC64: OK | AD64: OK | AI64: 2 | AJ64: 0.74 | AK64: =COUNTIF(E64:AE64,"ok")+AI64 -> 24 | AM64: =AJ64*AK64 -> 17.76 | AO64: AD
A65: ='[1]final 5-J'!A21 -> 11 | B65: ='RELACION GENERAL'!B16 -> SANCHEZ SANTIAGO KALEB MOISES | E65: OK | F65: OK | G65: OK | H65: OK | I65: OK | J65: OK | K65: OK | L65: OK | M65: OK | O65: OK | P65: OK | R65: OK | S65: OK | T65: Ok | U65: ok | V65: ok | W65: OK | X65: OK | Y65: OK | Z65: OK | AA65: OK | AB65: OK | AC65: OK | AD65: OK | AI65: 2 | AJ65: 0.74 | AK65: =COUNTIF(E65:AE65,"ok")+AI65 -> 26 | AM65: =AJ65*AK65 -> 19.24 | AO65: AD
A66: ='[1]final 5-J'!A22 -> 12 | B66: ='RELACION GENERAL'!B17 -> SEGOVIA LICAS DANGELO KENDALL | E66: OK | F66: OK | G66: OK | H66: OK | I66: OK | J66: OK | K66: OK | L66: OK | M66: OK | O66: OK | P66: OK | R66: OK | S66: OK | T66: Ok | U66: ok | V66: ok | W66: OK | X66: OK | Y66: OK | AA66: OK | AB66: OK | AC66: OK | AD66: OK | AI66: 2 | AJ66: 0.74 | AK66: =COUNTIF(E66:AE66,"ok")+AI66 -> 25 | AM66: =AJ66*AK66 -> 18.5 | AO66: AD
...

Sheet 5I-1ER-B-ASIST
A1: REGISTRO AUXILIAR DE EDUCACIÓN PARA EL TRABAJO - ELECTRICIDAD - 2021 -- 1º BIMESTRE
A2: Nº DE ORDEN | C2: I. E. | Z2: Promedio de Capacidades y Actitudes | AF2: Promedio de Capacidades y Actitudes
C3: "SAN LUIS GONZAGA" | H3: APLICA HABILIDADES Y TECNICAS | L3: TRABAJA COOPERATIVAMENTE PARA LOGRAR OBJETIVOS Y METAS | P3: EVALUA LOS RESULTADOS DEL PROYECTO | T3: SE DESEMVUELVE EN ENTORNOS VIRTUALES GENERDAS POR LAS TIC | W3: GESTIONA SU APRENDIZAJE DE MAERA AUTONOMA | Z3: PC-1 | AA3: PC-2 | AB3: PC-3 | AC3: PC-4 | AD3: PC-4 | AE3: PC-4 | AF3: PC-1 | AG3: PC-2 | AH3: PC-3
B4: ESPECIALIDAD: ELECTRICIDAD | E4: Evaluación Diagnostica: Desarrolla la gestion de propuesta de valor con ideas creativa y puntos de vista reveladores | G4: PROMEDIO C-1 | H4: Gestiona emprendimientos economicos o sociales de su interes proponiendo un reto o desafio y realizando la empatia para recoger datos | I4: reconoce y valora la seguridad electrica en su lugar de trabajo o estudio | J4: Promueve y ejecuta actividades de prevensión frente a un riesgo electrico | K4: PROMEDIO C-2 | L4: Trabaja cooperativamente recombinado sus roles y responsabilidades individuales para el logro de la competencia | M4: Organiza su area de trabajo para su adecuado trabajo remoto y uso de TIC | O4: PROMEDIO C-3 | P4: Implementa tecnicas (malla receptora) optimamente para evaluar su proptotipo y proyecto de meprendimiento | Q4: Incorpora mejoras innovadoras y creativas en el proyecto basico de emprendimiento orientado a la especialidad de EPT. | S4: PROMEDIO C-4 | T4: Se desenvuelve en los entornos virtuales cuando integra distintas actividades, actitudes y conocimientos de diversos contextos | W4: Gestiona su aprendizaje de manera autónoma al darse cuenta lo que debe aprender al distinguir lo sencillo o complejo de una tarea, y por ende define metas personales respaldándose en sus potencialidades
B5: GRADO Y SECCIÓN: 5 "J"
B6: BIMESTRE: I
B7: PROFESOR (A): Julio César
B8: SORIA QUISPE
B9: APELLIDOS Y NOMBRES
A11: 01 | E11: 16 | G11: =ROUND(AVERAGE(E11:F11),0) -> 16 | K11: =ROUND(AVERAGE(H11:J11),0) -> #DIV/0! | O11: =ROUND(AVERAGE(L11:N11),) -> #DIV/0! | Z11: =G11 -> 16 | AA11: =K11 -> #DIV/0! | AB11: =O11 -> #DIV/0! | AE11: =#REF! -> #REF! | AF11: =M11 -> 0 | AG11: =Q11 -> 0 | AH11: =U11 -> 0
A12: 02 | G12: =ROUND(AVERAGE(E12:F12),0) -> #DIV/0! | K12: =ROUND(AVERAGE(H12:J12),0) -> #DIV/0! | O12: =ROUND(AVERAGE(L12:N12),) -> #DIV/0! | Z12: =G12 -> #DIV/0! | AA12: =K12 -> #DIV/0! | AB12: =O12 -> #DIV/0! | AE12: =#REF! -> #REF! | AF12: =M12 -> 0 | AG12: =Q12 -> 0 | AH12: =U12 -> 0
A13: 03 | G13: =ROUND(AVERAGE(E13:F13),0) -> #DIV/0! | K13: =ROUND(AVERAGE(H13:J13),0) -> #DIV/0! | O13: =ROUND(AVERAGE(L13:N13),) -> #DIV/0! | Z13: =G13 -> #DIV/0! | AA13: =K13 -> #DIV/0! | AB13: =O13 -> #DIV/0! | AE13: =#REF! -> #REF! | AF13: =M13 -> 0 | AG13: =Q13 -> 0 | AH13: =U13 -> 0
A14: 04 | G14: =ROUND(AVERAGE(E14:F14),0) -> #DIV/0! | K14: =ROUND(AVERAGE(H14:J14),0) -> #DIV/0! | O14: =ROUND(AVERAGE(L14:N14),) -> #DIV/0! | Z14: =G14 -> #DIV/0! | AA14: =K14 -> #DIV/0! | AB14: =O14 -> #DIV/0! | AE14: =#REF! -> #REF! | AF14: =M14 -> 0 | AG14: =Q14 -> 0 | AH14: =U14 -> 0
A15: 05 | G15: =ROUND(AVERAGE(E15:F15),0) -> #DIV/0! | K15: =ROUND(AVERAGE(H15:J15),0) -> #DIV/0! | O15: =ROUND(AVERAGE(L15:N15),) -> #DIV/0! | Z15: =G15 -> #DIV/0! | AA15: =K15 -> #DIV/0! | AB15: =O15 -> #DIV/0! | AE15: =#REF! -> #REF! | AF15: =M15 -> 0 | AG15: =Q15 -> 0 | AH15: =U15 -> 0
A16: 06 | G16: =ROUND(AVERAGE(E16:F16),0) -> #DIV/0! | K16: =ROUND(AVERAGE(H16:J16),0) -> #DIV/0! | O16: =ROUND(AVERAGE(L16:N16),) -> #DIV/0! | Z16: =G16 -> #DIV/0! | AA16: =K16 -> #DIV/0! | AB16: =O16 -> #DIV/0! | AE16: =#REF! -> #REF! | AF16: =M16 -> 0 | AG16: =Q16 -> 0 | AH16: =U16 -> 0
A17: 07 | G17: =ROUND(AVERAGE(E17:F17),0) -> #DIV/0! | K17: =ROUND(AVERAGE(H17:J17),0) -> #DIV/0! | O17: =ROUND(AVERAGE(L17:N17),) -> #DIV/0! | Z17: =G17 -> #DIV/0! | AA17: =K17 -> #DIV/0! | AB17: =O17 -> #DIV/0! | AE17: =#REF! -> #REF! | AF17: =M17 -> 0 | AG17: =Q17 -> 0 | AH17: =U17 -> 0
A18: 08 | G18: =ROUND(AVERAGE(E18:F18),0) -> #DIV/0! | K18: =ROUND(AVERAGE(H18:J18),0) -> #DIV/0! | O18: =ROUND(AVERAGE(L18:N18),) -> #DIV/0! | Z18: =G18 -> #DIV/0! | AA18: =K18 -> #DIV/0! | AB18: =O18 -> #DIV/0! | AE18: =#REF! -> #REF! | AF18: =M18 -> 0 | AG18: =Q18 -> 0 | AH18: =U18 -> 0
A19: 09 | G19: =ROUND(AVERAGE(E19:F19),0) -> #DIV/0! | K19: =ROUND(AVERAGE(H19:J19),0) -> #DIV/0! | O19: =ROUND(AVERAGE(L19:N19),) -> #DIV/0! | Z19: =G19 -> #DIV/0! | AA19: =K19 -> #DIV/0! | AB19: =O19 -> #DIV/0! | AE19: =#REF! -> #REF! | AF19: =M19 -> 0 | AG19: =Q19 -> 0 | AH19: =U19 -> 0
A20: 10 | G20: =ROUND(AVERAGE(E20:F20),0) -> #DIV/0! | K20: =ROUND(AVERAGE(H20:J20),0) -> #DIV/0! | O20: =ROUND(AVERAGE(L20:N20),) -> #DIV/0! | Z20: =G20 -> #DIV/0! | AA20: =K20 -> #DIV/0! | AB20: =O20 -> #DIV/0! | AE20: =#REF! -> #REF! | AF20: =M20 -> 0 | AG20: =Q20 -> 0 | AH20: =U20 -> 0
A21: 11 | G21: =ROUND(AVERAGE(E21:F21),0) -> #DIV/0! | K21: =ROUND(AVERAGE(H21:J21),0) -> #DIV/0! | O21: =ROUND(AVERAGE(L21:N21),) -> #DIV/0! | Z21: =G21 -> #DIV/0! | AA21: =K21 -> #DIV/0! | AB21: =O21 -> #DIV/0! | AE21: =#REF! -> #REF! | AF21: =M21 -> 0 | AG21: =Q21 -> 0 | AH21: =U21 -> 0
A22: 12 | G22: =ROUND(AVERAGE(E22:F22),0) -> #DIV/0! | K22: =ROUND(AVERAGE(H22:J22),0) -> #DIV/0! | O22: =ROUND(AVERAGE(L22:N22),) -> #DIV/0! | Z22: =G22 -> #DIV/0! | AA22: =K22 -> #DIV/0! | AB22: =O22 -> #DIV/0! | AE22: =#REF! -> #REF! | AF22: =M22 -> 0 | AG22: =Q22 -> 0 | AH22: =U22 -> 0
A23: 13 | G23: =ROUND(AVERAGE(E23:F23),0) -> #DIV/0! | K23: =ROUND(AVERAGE(H23:J23),0) -> #DIV/0! | O23: =ROUND(AVERAGE(L23:N23),) -> #DIV/0! | Z23: =G23 -> #DIV/0! | AA23: =K23 -> #DIV/0! | AB23: =O23 -> #DIV/0! | AE23: =#REF! -> #REF! | AF23: =M23 -> 0 | AG23: =Q23 -> 0 | AH23: =U23 -> 0
... A43: 33 | G43: =ROUND(AVERAGE(E43:F43),0) -> #DIV/0! | K43: =ROUND(AVERAGE(H43:J43),0) -> #DIV/0! | O43: =ROUND(AVERAGE(L43:N43),) -> #DIV/0! | Z43: =G43 -> #DIV/0! | AA43: =K43 -> #DIV/0! | AB43: =O43 -> #DIV/0! | AE43: =#REF! -> #REF! | AF43: =M43 -> 0 | AG43: =Q43 -> 0 | AH43: =U43 -> 0
C49: REGISTRO DE ASISTENCIA DEL 5TO - I -- 2DO BIM
B50: QUINTO "I"
E52: SEMANA 11 | H52: SEMANA 12 | K52: SEMANA 13 | N52: SEMANA 14 | Q52: SEMANA 15 | T52: SEMANA 16 | W52: SEMANA 17 | Z52: SEMANA 18 | AC52: SEMANA 19 | AF52: SEMANA 20
E53: MARTES | F53: JUEVES | G53: VIERNES | H53: MARTES | I53: JUVES | J53: VIERNES | K53: MARTES | L53: JUEVES | M53: VIERNES | N53: MARTES | O53: JUVES | P53: VIERNES | Q53: MARTES | R53: JUEVES | S53: VIERNES | T53: MARTES | U53: JUVES | V53: VIERNES | W53: MARTES | X53: JUEVES | Y53: VIERNES | Z53: MARTES | AA53: JUVES | AB53: VIERNES | AC53: MARTES | AD53: JUEVES | AE53: VIERNES | AF53: MARTES | AG53: JUVES | AH53: VIERNES
A54: Nº | B54: APELLIDOS Y NOMBRES | C54: CELULARES - PP FF | D54: CELULARES | E54: 45804 | F54: =E54+2 -> 45806 | G54: =F54+1 -> 45807 | H54: =E54+7 -> 45811 | I54: =H54+2 -> 45813 | J54: =I54+1 -> 45814 | K54: =H54+7 -> 45818 | L54: =K54+2 -> 45820 | M54: =L54+1 -> 45821 | N54: =K54+7 -> 45825 | O54: =N54+2 -> 45827 | P54: =O54+1 -> 45828 | Q54: =N54+7 -> 45832 | R54: =Q54+2 -> 45834 | S54: =R54+1 -> 45835 | T54: =Q54+7 -> 45839 | U54: =T54+2 -> 45841 | V54: =U54+1 -> 45842 | W54: =T54+7 -> 45846 | X54: =W54+2 -> 45848 | Y54: =X54+1 -> 45849 | Z54: =W54+7 -> 45853 | AA54: =Z54+2 -> 45855 | AB54: =AA54+1 -> 45856 | AC54: =Z54+7 -> 45860 | AD54: =AC54+2 -> 45862 | AE54: =AD54+1 -> 45863 | AF54: =AC54+7 -> 45867 | AG54: =AF54+2 -> 45869 | AH54: =AG54+1 -> 45870
A55: ='[1]final 5-J'!A11 -> 01 | B55: ='RELACION GENERAL'!C6 -> CALDERON FALCON DORIAM JOSUE | E55: OK | F55: OK | G55: OK | H55: OK | I55: OK | J55: OK | K55: OK | L55: OK | M55: OK | N55: OK | O55: OK | P55: OK | Q55: OK | R55: OK | T55: OK | U55: OK | V55: OK | W55: OK | X55: OK | Y55: OK | Z55: OK | AA55: OK | AB55: DIA | AC55: ok | AD55: ok | AE55: FERIADO | AI55: 2 | AJ55: =COUNTIF(E55:AE55,"ok") -> 24 | AK55: =SUM(AI55:AJ55) -> 26 | AL55: 0.74 | AM55: =PRODUCT(AK55:AL55) -> 19.24 | AP55: AD
A56: ='[1]final 5-J'!A12 -> 02 | B56: ='RELACION GENERAL'!C7 -> CAMPOS PALOMINO MAXIMO NASSIR | F56: OK | G56: OK | J56: OK | K56: OK | L56: OK | M56: OK | N56: OK | O56: OK | Q56: OK | W56: OK | Y56: OK | Z56: OK | AA56: OK | AB56: DEL | AC56: ok | AD56: ok | AE56: DESFILE | AI56: 2 | AJ56: =COUNTIF(E56:AE56,"ok") -> 15 | AK56: =SUM(AI56:AJ56) -> 17 | AL56: 0.74 | AM56: =PRODUCT(AK56:AL56) -> 12.58 | AP56: B
A57: ='[1]final 5-J'!A13 -> 03 | B57: ='RELACION GENERAL'!C8 -> CHUQUIZUTA VALENCIA FRANKLIN YAZID | F57: OK | G57: OK | H57: OK | I57: OK | J57: OK | K57: OK | L57: OK | R57: OK | S57: OK | U57: OK | Y57: OK | Z57: OK | AA57: OK | AB57: LOGRO | AC57: ok | AD57: ok | AI57: 2 | AJ57: =COUNTIF(E57:AE57,"ok") -> 15 | AK57: =SUM(AI57:AJ57) -> 17 | AL57: 0.74 | AM57: =PRODUCT(AK57:AL57) -> 12.58 | AP57: B
A58: ='[1]final 5-J'!A14 -> 04 | B58: ='RELACION GENERAL'!C9 -> COTAQUISPE GALVEZ YOJAN ANDRES | E58: OK | F58: OK | G58: OK | H58: OK | J58: OK | K58: OK | L58: OK | M58: OK | N58: OK | O58: OK | P58: OK | Q58: OK | R58: OK | T58: OK | U58: OK | V58: OK | W58: OK | X58: OK | Y58: OK | AA58: OK | AC58: ok | AD58: ok | AI58: 2 | AJ58: =COUNTIF(E58:AE58,"ok") -> 22 | AK58: =SUM(AI58:AJ58) -> 24 | AL58: 0.74 | AM58: =PRODUCT(AK58:AL58) -> 17.76 | AP58: A
A59: ='[1]final 5-J'!A15 -> 05 | B59: ='RELACION GENERAL'!C10 -> HUAMANI PAUCAR LUIS ALFREDO | E59: OK | F59: OK | G59: OK | H59: OK | I59: OK | J59: OK | K59: OK | L59: OK | M59: OK | O59: OK | P59: OK | Q59: OK | R59: OK | S59: OK | T59: OK | U59: OK | V59: OK | W59: OK | X59: OK | Y59: OK | Z59: OK | AA59: OK | AC59: ok | AD59: ok | AI59: 2 | AJ59: =COUNTIF(E59:AE59,"ok") -> 24 | AK59: =SUM(AI59:AJ59) -> 26 | AL59: 0.74 | AM59: =PRODUCT(AK59:AL59) -> 19.24 | AP59: AD
A60: ='[1]final 5-J'!A16 -> 06 | B60: ='RELACION GENERAL'!C11 -> HUARCAYA BACAS HENRY VICENTE | E60: OK | F60: OK | G60: OK | H60: OK | I60: OK | J60: OK | K60: OK | L60: OK | M60: OK | N60: OK | O60: OK | P60: OK | Q60: OK | R60: OK | S60: OK | T60: OK | U60: OK | V60: OK | W60: OK | X60: OK | Y60: OK | Z60: OK | AA60: OK | AC60: ok | AD60: ok | AI60: 2 | AJ60: =COUNTIF(E60:AE60,"ok") -> 25 | AK60: =SUM(AI60:AJ60) -> 27 | AL60: 0.74 | AM60: =PRODUCT(AK60:AL60) -> 19.98 | AP60: AD
A61: ='[1]final 5-J'!A17 -> 07 | B61: ='RELACION GENERAL'!C12 -> HUAYHUAMEZA LEÑAN DEYVIS | E61: OK | F61: OK | G61: OK | H61: OK | I61: OK | J61: OK | K61: OK | L61: OK | M61: OK | N61: OK | O61: OK | Q61: OK | R61: OK | S61: OK | T61: OK | U61: OK | V61: OK | W61: OK | X61: OK | Y61: OK | Z61: OK | AA61: OK | AC61: ok | AD61: ok | AI61: 2 | AJ61: =COUNTIF(E61:AE61,"ok") -> 24 | AK61: =SUM(AI61:AJ61) -> 26 | AL61: 0.74 | AM61: =PRODUCT(AK61:AL61) -> 19.24 | AP61: AD
A62: ='[1]final 5-J'!A18 -> 08 | B62: ='RELACION GENERAL'!C13 -> JUSCAMAYTA HUARACC YOSSIMAR BAYRON | E62: OK | F62: OK | G62: OK | H62: OK | I62: OK | J62: OK | K62: OK | L62: OK | M62: OK | N62: OK | O62: OK | P62: OK | Q62: OK | R62: OK | T62: OK | U62: OK | W62: OK | X62: OK | Y62: OK | Z62: OK | AA62: OK | AC62: ok | AD62: ok | AI62: 2 | AJ62: =COUNTIF(E62:AE62,"ok") -> 23 | AK62: =SUM(AI62:AJ62) -> 25 | AL62: 0.74 | AM62: =PRODUCT(AK62:AL62) -> 18.5 | AP62: AD
A63: ='[1]final 5-J'!A19 -> 09 | B63: ='RELACION GENERAL'!C14 -> LEVANO GALINDO CRISTOPHER ANDRES | E63: OK | F63: OK | G63: OK | H63: OK | I63: OK | J63: OK | K63: OK | L63: OK | M63: OK | N63: OK | O63: OK | P63: OK | Q63: OK | R63: OK | T63: OK | U63: OK | V63: OK | W63: OK | X63: OK | Y63: OK | Z63: OK | AA63: OK | AC63: ok | AD63: ok | AI63: 2 | AJ63: =COUNTIF(E63:AE63,"ok") -> 24 | AK63: =SUM(AI63:AJ63) -> 26 | AL63: 0.74 | AM63: =PRODUCT(AK63:AL63) -> 19.24 | AP63: AD
A64: ='[1]final 5-J'!A20 -> 10 | B64: ='RELACION GENERAL'!C15 -> LINARES ZAPATA CARLOS ALBERTO | E64: OK | G64: OK | K64: OK | L64: OK | M64: OK | N64: OK | Q64: OK | R64: OK | T64: OK | U64: OK | W64: OK | X64: OK | Y64: OK | Z64: OK | AA64: OK | AC64: ok | AD64: ok | AI64: 2 | AJ64: =COUNTIF(E64:AE64,"ok") -> 17 | AK64: =SUM(AI64:AJ64) -> 19 | AL64: 0.74 | AM64: =PRODUCT(AK64:AL64) -> 14.06 | AP64: B
A65: ='[1]final 5-J'!A21 -> 11 | B65: ='RELACION GENERAL'!C16 -> MOZO HUAYRA PEDRO CALEB | E65: OK | F65: OK | G65: OK | H65: OK | I65: OK | J65: OK | K65: OK | L65: OK | M65: OK | N65: OK | O65: OK | Q65: OK | R65: OK | S65: OK | T65: OK | U65: OK | V65: OK | W65: OK | X65: OK | Y65: OK | Z65: OK | AA65: OK | AC65: ok | AD65: ok | AI65: 2 | AJ65: =COUNTIF(E65:AE65,"ok") -> 24 | AK65: =SUM(AI65:AJ65) -> 26 | AL65: 0.74 | AM65: =PRODUCT(AK65:AL65) -> 19.24 | AP65: AD
A66: ='[1]final 5-J'!A22 -> 12 | B66: ='RELACION GENERAL'!C17 -> NECOCHEA CASTILLO ANTHONY ORLANDO | E66: OK | F66: OK | G66: OK | H66: OK | I66: OK | J66: OK | K66: OK | L66: OK | M66: OK | O66: OK | P66: OK | Q66: OK | R66: OK | U66: OK | W66: OK | X66: OK | Y66: OK | Z66: OK | AA66: OK | AC66: ok | AD66: ok | AI66: 2 | AJ66: =COUNTIF(E66:AE66,"ok") -> 21 | AK66: =SUM(AI66:AJ66) -> 23 | AL66: 0.74 | AM66: =PRODUCT(AK66:AL66) -> 17.02 | AP66: A
...

Sheet 5R-1ER-B-ASIST
A1: REGISTRO AUXILIAR DE EDUCACIÓN PARA EL TRABAJO - ELECTRICIDAD - 2021 -- 1º BIMESTRE
A2: Nº DE ORDEN | C2: I. E. | Z2: Promedio de Capacidades y Actitudes | AF2: Promedio de Capacidades y Actitudes
C3: "SAN LUIS GONZAGA" | H3: APLICA HABILIDADES Y TECNICAS | L3: TRABAJA COOPERATIVAMENTE PARA LOGRAR OBJETIVOS Y METAS | P3: EVALUA LOS RESULTADOS DEL PROYECTO | T3: SE DESEMVUELVE EN ENTORNOS VIRTUALES GENERDAS POR LAS TIC | W3: GESTIONA SU APRENDIZAJE DE MAERA AUTONOMA | Z3: PC-1 | AA3: PC-2 | AB3: PC-3 | AC3: PC-4 | AD3: PC-4 | AE3: PC-4 | AF3: PC-1 | AG3: PC-2 | AH3: PC-3
B4: ESPECIALIDAD: ELECTRICIDAD | E4: Evaluación Diagnostica: Desarrolla la gestion de propuesta de valor con ideas creativa y puntos de vista reveladores | G4: PROMEDIO C-1 | H4: Gestiona emprendimientos economicos o sociales de su interes proponiendo un reto o desafio y realizando la empatia para recoger datos | I4: reconoce y valora la seguridad electrica en su lugar de trabajo o estudio | J4: Promueve y ejecuta actividades de prevensión frente a un riesgo electrico | K4: PROMEDIO C-2 | L4: Trabaja cooperativamente recombinado sus roles y responsabilidades individuales para el logro de la competencia | M4: Organiza su area de trabajo para su adecuado trabajo remoto y uso de TIC | O4: PROMEDIO C-3 | P4: Implementa tecnicas (malla receptora) optimamente para evaluar su proptotipo y proyecto de meprendimiento | Q4: Incorpora mejoras innovadoras y creativas en el proyecto basico de emprendimiento orientado a la especialidad de EPT. | S4: PROMEDIO C-4 | T4: Se desenvuelve en los entornos virtuales cuando integra distintas actividades, actitudes y conocimientos de diversos contextos | W4: Gestiona su aprendizaje de manera autónoma al darse cuenta lo que debe aprender al distinguir lo sencillo o complejo de una tarea, y por ende define metas personales respaldándose en sus potencialidades
B5: GRADO Y SECCIÓN: 5 "J"
B6: BIMESTRE: I
B7: PROFESOR (A): Julio César
B8: SORIA QUISPE
B9: APELLIDOS Y NOMBRES
A11: 01 | E11: 16 | G11: =ROUND(AVERAGE(E11:F11),0) -> 16 | K11: =ROUND(AVERAGE(H11:J11),0) -> #DIV/0! | O11: =ROUND(AVERAGE(L11:N11),) -> #DIV/0! | Z11: =G11 -> 16 | AA11: =K11 -> #DIV/0! | AB11: =O11 -> #DIV/0! | AE11: =#REF! -> #REF! | AF11: =M11 -> 0 | AG11: =Q11 -> 0 | AH11: =U11 -> 0
A12: 02 | G12: =ROUND(AVERAGE(E12:F12),0) -> #DIV/0! | K12: =ROUND(AVERAGE(H12:J12),0) -> #DIV/0! | O12: =ROUND(AVERAGE(L12:N12),) -> #DIV/0! | Z12: =G12 -> #DIV/0! | AA12: =K12 -> #DIV/0! | AB12: =O12 -> #DIV/0! | AE12: =#REF! -> #REF! | AF12: =M12 -> 0 | AG12: =Q12 -> 0 | AH12: =U12 -> 0
A13: 03 | G13: =ROUND(AVERAGE(E13:F13),0) -> #DIV/0! | K13: =ROUND(AVERAGE(H13:J13),0) -> #DIV/0! | O13: =ROUND(AVERAGE(L13:N13),) -> #DIV/0! | Z13: =G13 -> #DIV/0! | AA13: =K13 -> #DIV/0! | AB13: =O13 -> #DIV/0! | AE13: =#REF! -> #REF! | AF13: =M13 -> 0 | AG13: =Q13 -> 0 | AH13: =U13 -> 0
A14: 04 | G14: =ROUND(AVERAGE(E14:F14),0) -> #DIV/0! | K14: =ROUND(AVERAGE(H14:J14),0) -> #DIV/0! | O14: =ROUND(AVERAGE(L14:N14),) -> #DIV/0! | Z14: =G14 -> #DIV/0! | AA14: =K14 -> #DIV/0! | AB14: =O14 -> #DIV/0! | AE14: =#REF! -> #REF! | AF14: =M14 -> 0 | AG14: =Q14 -> 0 | AH14: =U14 -> 0
A15: 05 | G15: =ROUND(AVERAGE(E15:F15),0) -> #DIV/0! | K15: =ROUND(AVERAGE(H15:J15),0) -> #DIV/0! | O15: =ROUND(AVERAGE(L15:N15),) -> #DIV/0! | Z15: =G15 -> #DIV/0! | AA15: =K15 -> #DIV/0! | AB15: =O15 -> #DIV/0! | AE15: =#REF! -> #REF! | AF15: =M15 -> 0 | AG15: =Q15 -> 0 | AH15: =U15 -> 0
A16: 06 | G16: =ROUND(AVERAGE(E16:F16),0) -> #DIV/0! | K16: =ROUND(AVERAGE(H16:J16),0) -> #DIV/0! | O16: =ROUND(AVERAGE(L16:N16),) -> #DIV/0! | Z16: =G16 -> #DIV/0! | AA16: =K16 -> #DIV/0! | AB16: =O16 -> #DIV/0! | AE16: =#REF! -> #REF! | AF16: =M16 -> 0 | AG16: =Q16 -> 0 | AH16: =U16 -> 0
A17: 07 | G17: =ROUND(AVERAGE(E17:F17),0) -> #DIV/0! | K17: =ROUND(AVERAGE(H17:J17),0) -> #DIV/0! | O17: =ROUND(AVERAGE(L17:N17),) -> #DIV/0! | Z17: =G17 -> #DIV/0! | AA17: =K17 -> #DIV/0! | AB17: =O17 -> #DIV/0! | AE17: =#REF! -> #REF! | AF17: =M17 -> 0 | AG17: =Q17 -> 0 | AH17: =U17 -> 0
A18: 08 | G18: =ROUND(AVERAGE(E18:F18),0) -> #DIV/0! | K18: =ROUND(AVERAGE(H18:J18),0) -> #DIV/0! | O18: =ROUND(AVERAGE(L18:N18),) -> #DIV/0! | Z18: =G18 -> #DIV/0! | AA18: =K18 -> #DIV/0! | AB18: =O18 -> #DIV/0! | AE18: =#REF! -> #REF! | AF18: =M18 -> 0 | AG18: =Q18 -> 0 | AH18: =U18 -> 0
A19: 09 | G19: =ROUND(AVERAGE(E19:F19),0) -> #DIV/0! | K19: =ROUND(AVERAGE(H19:J19),0) -> #DIV/0! | O19: =ROUND(AVERAGE(L19:N19),) -> #DIV/0! | Z19: =G19 -> #DIV/0! | AA19: =K19 -> #DIV/0! | AB19: =O19 -> #DIV/0! | AE19: =#REF! -> #REF! | AF19: =M19 -> 0 | AG19: =Q19 -> 0 | AH19: =U19 -> 0
A20: 10 | G20: =ROUND(AVERAGE(E20:F20),0) -> #DIV/0! | K20: =ROUND(AVERAGE(H20:J20),0) -> #DIV/0! | O20: =ROUND(AVERAGE(L20:N20),) -> #DIV/0! | Z20: =G20 -> #DIV/0! | AA20: =K20 -> #DIV/0! | AB20: =O20 -> #DIV/0! | AE20: =#REF! -> #REF! | AF20: =M20 -> 0 | AG20: =Q20 -> 0 | AH20: =U20 -> 0
A21: 11 | G21: =ROUND(AVERAGE(E21:F21),0) -> #DIV/0! | K21: =ROUND(AVERAGE(H21:J21),0) -> #DIV/0! | O21: =ROUND(AVERAGE(L21:N21),) -> #DIV/0! | Z21: =G21 -> #DIV/0! | AA21: =K21 -> #DIV/0! | AB21: =O21 -> #DIV/0! | AE21: =#REF! -> #REF! | AF21: =M21 -> 0 | AG21: =Q21 -> 0 | AH21: =U21 -> 0
A22: 12 | G22: =ROUND(AVERAGE(E22:F22),0) -> #DIV/0! | K22: =ROUND(AVERAGE(H22:J22),0) -> #DIV/0! | O22: =ROUND(AVERAGE(L22:N22),) -> #DIV/0! | Z22: =G22 -> #DIV/0! | AA22: =K22 -> #DIV/0! | AB22: =O22 -> #DIV/0! | AE22: =#REF! -> #REF! | AF22: =M22 -> 0 | AG22: =Q22 -> 0 | AH22: =U22 -> 0
A23: 13 | G23: =ROUND(AVERAGE(E23:F23),0) -> #DIV/0! | K23: =ROUND(AVERAGE(H23:J23),0) -> #DIV/0! | O23: =ROUND(AVERAGE(L23:N23),) -> #DIV/0! | Z23: =G23 -> #DIV/0! | AA23: =K23 -> #DIV/0! | AB23: =O23 -> #DIV/0! | AE23: =#REF! -> #REF! | AF23: =M23 -> 0 | AG23: =Q23 -> 0 | AH23: =U23 -> 0
... A43: 33 | G43: =ROUND(AVERAGE(E43:F43),0) -> #DIV/0! | K43: =ROUND(AVERAGE(H43:J43),0) -> #DIV/0! | O43: =ROUND(AVERAGE(L43:N43),) -> #DIV/0! | Z43: =G43 -> #DIV/0! | AA43: =K43 -> #DIV/0! | AB43: =O43 -> #DIV/0! | AE43: =#REF! -> #REF! | AF43: =M43 -> 0 | AG43: =Q43 -> 0 | AH43: =U43 -> 0
C49: REGISTRO DE ASISTENCIA DEL 5TO - I -- 2DO BIM
B50: QUINTO "R"
E52: SEMANA 11 | H52: SEMANA 12 | K52: SEMANA 13 | N52: SEMANA 14 | Q52: SEMANA 15 | T52: SEMANA 16 | W52: SEMANA 17 | Z52: SEMANA 18 | AC52: SEMANA 19 | AF52: SEMANA 20
E53: LUNES | F53: MARTES | G53: VIERNES | H53: LUNES | I53: MARTES | J53: VIERNES | K53: LUNES | L53: MARTES | M53: VIERNES | N53: LUNES | O53: MARTES | P53: VIERNES | Q53: LUNES | R53: MARTES | S53: VIERNES | T53: MARTES | U53: MIERCOLES | V53: JUEVES | W53: MARTES | X53: MIERCOLES | Y53: JUEVES | Z53: MARTES | AA53: MIERCOLES | AB53: JUEVES | AC53: MARTES | AD53: MIERCOLES | AE53: JUEVES | AF53: MARTES | AG53: MIERCOLES | AH53: JUEVES
A54: Nº | B54: APELLIDOS Y NOMBRES | C54: CELULARES - PP FF | D54: CELULARES | E54: 45803 | F54: =E54+1 -> 45804 | G54: =E54+4 -> 45807 | H54: =E54+7 -> 45810 | I54: =H54+1 -> 45811 | J54: =I54+3 -> 45814 | K54: =H54+7 -> 45817 | L54: =K54+1 -> 45818 | M54: =L54+3 -> 45821 | N54: =K54+7 -> 45824 | O54: =N54+1 -> 45825 | P54: =O54+3 -> 45828 | Q54: =N54+7 -> 45831 | R54: =Q54+1 -> 45832 | S54: =R54+3 -> 45835 | T54: =Q54+7 -> 45838 | U54: =T54+1 -> 45839 | V54: =U54+3 -> 45842 | W54: =T54+7 -> 45845 | X54: =W54+1 -> 45846 | Y54: =X54+3 -> 45849 | Z54: =W54+7 -> 45852 | AA54: =Z54+1 -> 45853 | AB54: =AA54+3 -> 45856 | AC54: =Z54+7 -> 45859 | AD54: =AC54+1 -> 45860 | AE54: =AD54+3 -> 45863 | AF54: =AC54+7 -> 45866 | AG54: =AF54+1 -> 45867 | AH54: =AG54+3 -> 45870
A55: ='[1]final 5-J'!A11 -> 01 | B55: ='RELACION GENERAL'!D6 -> APUMAITA GUTIERREZ JULIO LUCIANO | E55: OK | F55: OK | H55: OK | I55: OK | J55: OK | K55: OK | M55: OK | N55: OK | O55: OK | P55: OK | Q55: DIA | R55: OK | S55: OK | T55: ok | Z55: OK | AA55: OK | AB55: DIA | AD55: OK | AE55: FERIADO | AI55: 3 | AJ55: =COUNTIF(E55:AE55,"ok") -> 16 | AK55: =SUM(AI55:AJ55) -> 19 | AL55: 0.74 | AM55: =PRODUCT(AK55:AL55) -> 14.06 | AN55: B
A56: ='[1]final 5-J'!A12 -> 02 | B56: ='RELACION GENERAL'!D7 -> CABRERA ORTIZ THIAGO ARMANDO | E56: OK | F56: OK | G56: OK | I56: OK | J56: OK | K56: OK | M56: OK | P56: OK | Q56: NO | R56: OK | S56: OK | T56: ok | W56: OK | X56: OK | Y56: OK | Z56: OK | AA56: OK | AB56: DEL | AC56: OK | AD56: OK | AE56: FIESTAS | AI56: 3 | AJ56: =COUNTIF(E56:AE56,"ok") -> 18 | AK56: =SUM(AI56:AJ56) -> 21 | AL56: 0.74 | AM56: =PRODUCT(AK56:AL56) -> 15.54 | AN56: A
A57: ='[1]final 5-J'!A13 -> 03 | B57: ='RELACION GENERAL'!D8 -> CACERES CAHUANA JESUS ANDRES | F57: OK | G57: OK | H57: OK | I57: OK | K57: OK | L57: OK | M57: OK | P57: OK | Q57: LAB | R57: OK | S57: OK | T57: ok | U57: ok | W57: OK | X57: OK | Y57: OK | Z57: OK | AA57: OK | AB57: LOGRO | AD57: OK | AE57: PATRIAS | AI57: 3 | AJ57: =COUNTIF(E57:AE57,"ok") -> 18 | AK57: =SUM(AI57:AJ57) -> 21 | AL57: 0.74 | AM57: =PRODUCT(AK57:AL57) -> 15.54 | AN57: A
A58: ='[1]final 5-J'!A14 -> 04 | B58: ='RELACION GENERAL'!D9 -> DE LA CRUZ SIGUAS LUIS ALBERTO | F58: OK | G58: OK | I58: OK | K58: OK | M58: OK | N58: OK | O58: OK | Q58: ANIVERS. | R58: OK | S58: OK | V58: ok | W58: OK | AA58: OK | AI58: 3 | AJ58: =COUNTIF(E58:AE58,"ok") -> 12 | AK58: =SUM(AI58:AJ58) -> 15 | AL58: 0.74 | AM58: =PRODUCT(AK58:AL58) -> 11.1 | AN58: B
A59: ='[1]final 5-J'!A15 -> 05 | B59: ='RELACION GENERAL'!D10 -> HERNANDEZ PEÑA JOSEPH ANDREE | F59: OK | H59: OK | I59: OK | J59: OK | M59: OK | N59: OK | O59: OK | R59: OK | S59: OK | U59: ok | W59: OK | X59: OK | Y59: OK | Z59: OK | AA59: OK | AC59: OK | AI59: 3 | AJ59: =COUNTIF(E59:AE59,"ok") -> 16 | AK59: =SUM(AI59:AJ59) -> 19 | AL59: 0.74 | AM59: =PRODUCT(AK59:AL59) -> 14.06 | AN59: B
A60: ='[1]final 5-J'!A16 -> 06 | B60: ='RELACION GENERAL'!D11 -> JUAREZ LEGUA VICTOR DANIEL | E60: OK | F60: OK | G60: OK | H60: OK | I60: OK | J60: OK | K60: OK | L60: OK | M60: OK | N60: OK | O60: OK | P60: OK | R60: OK | S60: OK | T60: ok | U60: ok | V60: ok | W60: OK | X60: OK | Y60: OK | Z60: OK | AA60: OK | AC60: OK | AD60: OK | AI60: 3 | AJ60: =COUNTIF(E60:AE60,"ok") -> 24 | AK60: =SUM(AI60:AJ60) -> 27 | AL60: 0.74 | AM60: =PRODUCT(AK60:AL60) -> 19.98 | AN60: AD
A61: ='[1]final 5-J'!A17 -> 07 | B61: ='RELACION GENERAL'!D12 -> MEJIA SIMON VICENTE MISAEL | E61: OK | F61: OK | G61: OK | H61: OK | I61: OK | J61: OK | K61: OK | L61: OK | M61: OK | N61: OK | O61: OK | P61: OK | R61: OK | S61: OK | T61: ok | U61: ok | V61: ok | W61: OK | X61: OK | Y61: OK | Z61: OK | AA61: OK | AC61: OK | AD61: OK | AI61: 3 | AJ61: =COUNTIF(E61:AE61,"ok") -> 24 | AK61: =SUM(AI61:AJ61) -> 27 | AL61: 0.74 | AM61: =PRODUCT(AK61:AL61) -> 19.98 | AN61: AD
A62: ='[1]final 5-J'!A18 -> 08 | B62: ='RELACION GENERAL'!D13 -> MEZA CARDENAS FERNANDO ALEXANDER | F62: OK | G62: OK | H62: OK | I62: OK | K62: OK | L62: OK | M62: OK | N62: OK | O62: OK | P62: OK | R62: OK | S62: OK | T62: ok | U62: ok | W62: OK | X62: OK | Y62: OK | Z62: OK | AA62: OK | AC62: OK | AD62: OK | AI62: 3 | AJ62: =COUNTIF(E62:AE62,"ok") -> 21 | AK62: =SUM(AI62:AJ62) -> 24 | AL62: 0.74 | AM62: =PRODUCT(AK62:AL62) -> 17.76 | AN62: A
A63: ='[1]final 5-J'!A19 -> 09 | B63: ='RELACION GENERAL'!D14 -> MISAICO CHAHUAILA JUAN DAVID | E63: OK | F63: OK | G63: OK | I63: OK | J63: OK | K63: OK | L63: OK | M63: OK | N63: OK | O63: OK | P63: OK | R63: OK | S63: OK | T63: ok | U63: ok | V63: ok | W63: OK | X63: OK | Y63: OK | Z63: OK | AA63: OK | AC63: OK | AD63: OK | AI63: 3 | AJ63: =COUNTIF(E63:AE63,"ok") -> 23 | AK63: =SUM(AI63:AJ63) -> 26 | AL63: 0.74 | AM63: =PRODUCT(AK63:AL63) -> 19.24 | AN63: AD
A64: ='[1]final 5-J'!A20 -> 10 | B64: ='RELACION GENERAL'!D15 -> MUÑOZ QUINTANILLA JACKXEL EDUARDO | F64: OK | H64: OK | I64: OK | J64: OK | M64: OK | N64: OK | O64: OK | R64: OK | S64: OK | T64: ok | U64: ok | V64: ok | W64: OK | X64: OK | Y64: OK | Z64: OK | AA64: OK | AD64: OK | AI64: 3 | AJ64: =COUNTIF(E64:AE64,"ok") -> 18 | AK64: =SUM(AI64:AJ64) -> 21 | AL64: 0.74 | AM64: =PRODUCT(AK64:AL64) -> 15.54 | AN64: A
A65: ='[1]final 5-J'!A21 -> 11 | B65: ='RELACION GENERAL'!D16 -> PEÑA ASCENCIO CESAR LUIS | E65: OK | F65: OK | H65: OK | I65: OK | K65: OK | L65: OK | M65: OK | N65: OK | O65: OK | R65: OK | S65: OK | T65: ok | U65: ok | W65: OK | X65: OK | Y65: OK | Z65: OK | AA65: OK | AC65: OK | AI65: 3 | AJ65: =COUNTIF(E65:AE65,"ok") -> 19 | AK65: =SUM(AI65:AJ65) -> 22 | AL65: 0.74 | AM65: =PRODUCT(AK65:AL65) -> 16.28 | AN65: A
A66: ='[1]final 5-J'!A22 -> 12 | B66: ='RELACION GENERAL'!D17 -> SOSA FUENTES UBALDO FRANCISCO | E66: OK | F66: OK | G66: OK | H66: OK | I66: OK | M66: OK | S66: OK | T66: ok | U66: ok | V66: ok | X66: OK | Y66: OK | AA66: OK | AI66: 3 | AJ66: =COUNTIF(E66:AE66,"ok") -> 13 | AK66: =SUM(AI66:AJ66) -> 16 | AL66: 0.74 | AM66: =PRODUCT(AK66:AL66) -> 11.84 | AN66: B
...
